Workbook

Sheet Data
B1: =IF(B2<>"",COLUMN(B2),"") -> 2 | C1: =IF(C2<>"",COLUMN(C2),"") -> 3 | D1: =IF(D2<>"",COLUMN(D2),"") -> 4 | E1: =IF(E2<>"",COLUMN(E2),"") -> 5 | F1: =IF(F2<>"",COLUMN(F2),"") -> 6 | G1: =IF(G2<>"",COLUMN(G2),"") -> 7 | H1: =IF(H2<>"",COLUMN(H2),"") -> 8 | I1: =IF(I2<>"",COLUMN(I2),"") -> 9 | ... X1: =IF(X2<>"",COLUMN(X2),"") -> 24
A2: Bilanço | B2: 2025/9 | C2: 2025/6 | D2: 2025/3 | E2: 2024/12 | F2: 2024/9 | G2: 2024/6 | H2: 2024/3 | I2: 2023/12 | J2: 2023/9 | K2: 2023/6 | L2: 2023/3 | M2: 2022/12 | N2: 2022/9 | O2: 2022/6 | P2: 2022/3 | Q2: 2021/12 | R2: 2021/9 | S2: 2021/6 | T2: 2021/3 | U2: 2020/12 | V2: 2020/9 | W2: 2020/6 | X2: 2020/3
A3: Dönen Varlıklar | B3: 90083589000 | C3: 84668198000 | D3: 77284896000 | E3: 81667657435 | F3: 58862926000 | G3: 47885764000 | H3: 43524184000 | I3: 53401735000 | J3: 31285963000 | K3: 29099280000 | L3: 28508097000 | M3: 41773214000 | N3: 25073546000 | O3: 22487525000 | P3: 20954562000 | Q3: 18764940000 | R3: 13852909000 | S3: 15405235000 | T3: 15365396000 | U3: 14701119000 | V3: 11927735000 | W3: 10298815000 | X3: 9224526000
A4: Nakit ve Nakit Benzerleri | B4: 29570256000 | C4: 27391388000 | D4: 23936928000 | E4: 32998196584 | F4: 23329331000 | G4: 16724845000 | H4: 12662493000 | I4: 16830554000 | J4: 9682950000 | K4: 8758014000 | L4: 9861492000 | M4: 15249460000 | N4: 3765411000 | O4: 3324052000 | P4: 2985113000 | Q4: 3004834000 | R4: 2862609000 | S4: 2762136000 | T4: 3367634000 | U4: 3835520000 | V4: 3532368000 | W4: 2956000000 | X4: 1219355000
A5: Finansal Yatırımlar | B5: 6245000 | C5: 6021000 | D5: 5768000 | E5: 6827132 | F5: 4825000 | G5: 4664000 | H5: 4594000 | I5: 6107000 | J5: 3565000 | K5: 3957000 | L5: 3200000 | M5: 346842000 | N5: 5721346000 | O5: 6366126000 | P5: 6345108000 | Q5: 6414869000 | R5: 4277960000 | S5: 6005890000 | T5: 5597490000 | U5: 3639474000 | V5: 2374641000 | W5: 3605728000 | X5: 3820230000
A6: Ticari Alacaklar | B6: 29618330000 | C6: 26522023000 | D6: 27378948000 | E6: 27468684631 | F6: 18441357000 | G6: 15131201000 | H6: 16356844000 | I6: 17421913000 | J6: 10893157000 | K6: 9892760000 | L6: 9524879000 | M6: 12173983000 | N6: 7042688000 | O6: 5789621000 | P6: 5856073000 | Q6: 4687911000 | R6: 3642113000 | S6: 3284920000 | T6: 3256697000 | U6: 3092000000 | V6: 2889558000 | W6: 2577242000 | X6: 2726899000
A7: Finans Sektörü Faaliyetlerinden Alacaklar | B7: 0 | C7: 0 | D7: 0 | E7: 0 | F7: 0 | G7: 0 | H7: 0 | I7: 0 | J7: 0 | K7: 0 | L7: 0 | M7: 0 | N7: 0 | O7: 0 | P7: 0 | Q7: 0 | R7: 0 | S7: 0 | T7: 0 | U7: 0 | V7: 0 | W7: 0 | X7: 0
A8: Diğer Alacaklar | B8: 2530647000 | C8: 2651416000 | D8: 2996655000 | E8: 3328891227 | F8: 2518982000 | G8: 2353734000 | H8: 2862491000 | I8: 3124601000 | J8: 2346415000 | K8: 2126914000 | L8: 1755461000 | M8: 2566503000 | N8: 1399047000 | O8: 1190109000 | P8: 948909000 | Q8: 614402000 | R8: 609152000 | S8: 2137532000 | T8: 1974940000 | U8: 2214736000 | V8: 1870764000 | W8: 158926000 | X8: 180177000
A9: Müşteri Sözleşmelerinden Doğan Varlıklar | B9: 0 | C9: 0 | D9: 0 | E9: 0 | F9: 0 | G9: 0 | H9: 0 | I9: 0 | J9: 0 | K9: 0 | L9: 0 | M9: 0 | N9: 0 | O9: 0 | P9: 0 | Q9: 0 | R9: 0 | S9: 0 | T9: 0 | U9: 0 | V9: 0 | W9: 0 | X9: 0
A10: Stoklar | B10: 23046205000 | C10: 23571112000 | D10: 19099042000 | E10: 14839141804 | F10: 10998733000 | G10: 10414885000 | H10: 8999055000 | I10: 12115210000 | J10: 6664345000 | K10: 6555159000 | L10: 5520627000 | M10: 8516384000 | N10: 5402135000 | O10: 4279769000 | P10: 3744893000 | Q10: 3218231000 | R10: 2028702000 | S10: 961339000 | T10: 928950000 | U10: 1695858000 | V10: 897909000 | W10: 804703000 | X10: 671929000
A11: Canlı Varlıklar | B11: 0 | C11: 0 | D11: 0 | E11: 0 | F11: 0 | G11: 0 | H11: 0 | I11: 0 | J11: 0 | K11: 0 | L11: 0 | M11: 0 | N11: 0 | O11: 0 | P11: 0 | Q11: 0 | R11: 0 | S11: 0 | T11: 0 | U11: 0 | V11: 0 | W11: 0 | X11: 0
A12: Diğer Dönen Varlıklar | B12: 5311906000 | C12: 4526238000 | D12: 3867555000 | E12: 3025916057 | F12: 3569698000 | G12: 3256435000 | H12: 2638707000 | I12: 3903350000 | J12: 1695531000 | K12: 1762476000 | L12: 1842438000 | M12: 2920042000 | N12: 1742919000 | O12: 1537848000 | P12: 1074466000 | Q12: 824693000 | R12: 432373000 | S12: 253418000 | T12: 239685000 | U12: 223531000 | V12: 362495000 | W12: 196216000 | X12: 605936000
A13: (Ara Toplam) | B13: 90083589000 | C13: 84668198000 | D13: 77284896000 | E13: 81667657435 | F13: 58862926000 | G13: 47885764000 | H13: 43524184000 | I13: 53401735000 | J13: 31285963000 | K13: 29099280000 | L13: 28508097000 | M13: 41773214000 | N13: 25073546000 | O13: 22487525000 | P13: 20954562000 | Q13: 18764940000 | R13: 13852909000 | S13: 15405235000 | T13: 15365396000 | U13: 14701119000 | V13: 11927735000 | W13: 10298815000 | X13: 9224526000
A14: Satış Amacıyla Elde Tutulan Duran Varlıklar | B14: 0 | C14: 0 | D14: 0 | E14: 0 | F14: 0 | G14: 0 | H14: 0 | I14: 0 | J14: 0 | K14: 0 | L14: 0 | M14: 0 | N14: 0 | O14: 0 | P14: 0 | Q14: 0 | R14: 0 | S14: 0 | T14: 0 | U14: 0 | V14: 0 | W14: 0 | X14: 0
... A149: Dönem Sonu Nakit | B149: 29570256000 | C149: 27391388000 | D149: 23936928000 | E149: 32998196584 | F149: 31096601000 | G149: 22586679000 | H149: 17487388000 | I149: 16830554000 | J149: 14464874000 | K149: 15028503000 | L149: 16616158000 | M149: 15249460000 | N149: 3765411000 | O149: 3324052000 | P149: 2985113000 | Q149: 3004834000 | R149: 2862609000 | S149: 3049937000 | T149: 3394555000 | U149: 3835520000 | V149: 3538025000 | W149: 2956000000 | X149: 1219355000

Sheet Bilanço
B1: =COUNT(Data!$1:$1)+1 -> 24 | C1: =($B$1+1)-COLUMN(B1) -> 23 | D1: =($B$1+1)-COLUMN(C1) -> 22 | E1: =($B$1+1)-COLUMN(D1) -> 21 | F1: =($B$1+1)-COLUMN(E1) -> 20 | G1: =($B$1+1)-COLUMN(F1) -> 19 | H1: =($B$1+1)-COLUMN(G1) -> 18 | I1: =($B$1+1)-COLUMN(H1) -> 17 | J1: =($B$1+1)-COLUMN(I1) -> 16 | ... Y1: =($B$1+1)-COLUMN(X1) -> 1
A2: =Data!A2 -> Bilanço | B2: =IFERROR(HLOOKUP(B$1,Data!$1:$149,ROW(Bilanço!$A2),0),"") -> 2020/3 | C2: =IFERROR(HLOOKUP(C$1,Data!$1:$149,ROW(Bilanço!$A2),0),"") -> 2020/6 | D2: =IFERROR(HLOOKUP(D$1,Data!$1:$149,ROW(Bilanço!$A2),0),"") -> 2020/9 | E2: =IFERROR(HLOOKUP(E$1,Data!$1:$149,ROW(Bilanço!$A2),0),"") -> 2020/12 | F2: =IFERROR(HLOOKUP(F$1,Data!$1:$149,ROW(Bilanço!$A2),0),"") -> 2021/3 | G2: =IFERROR(HLOOKUP(G$1,Data!$1:$149,ROW(Bilanço!$A2),0),"") -> 2021/6 | H2: =IFERROR(HLOOKUP(H$1,Data!$1:$149,ROW(Bilanço!$A2),0),"") -> 2021/9 | I2: =IFERROR(HLOOKUP(I$1,Data!$1:$149,ROW(Bilanço!$A2),0),"") -> 2021/12 | ... X2: =IFERROR(HLOOKUP(X$1,Data!$1:$149,ROW(Bilanço!$A2),0),"") -> 2025/9
A3: =Data!A3 -> Dönen Varlıklar | B3: =IFERROR(HLOOKUP(B$1,Data!$1:$149,ROW(Bilanço!$A3),0),"") -> 9224526000 | C3: =IFERROR(HLOOKUP(C$1,Data!$1:$149,ROW(Bilanço!$A3),0),"") -> 10298815000 | D3: =IFERROR(HLOOKUP(D$1,Data!$1:$149,ROW(Bilanço!$A3),0),"") -> 11927735000 | E3: =IFERROR(HLOOKUP(E$1,Data!$1:$149,ROW(Bilanço!$A3),0),"") -> 14701119000 | F3: =IFERROR(HLOOKUP(F$1,Data!$1:$149,ROW(Bilanço!$A3),0),"") -> 15365396000 | G3: =IFERROR(HLOOKUP(G$1,Data!$1:$149,ROW(Bilanço!$A3),0),"") -> 15405235000 | H3: =IFERROR(HLOOKUP(H$1,Data!$1:$149,ROW(Bilanço!$A3),0),"") -> 13852909000 | I3: =IFERROR(HLOOKUP(I$1,Data!$1:$149,ROW(Bilanço!$A3),0),"") -> 18764940000 | ... X3: =IFERROR(HLOOKUP(X$1,Data!$1:$149,ROW(Bilanço!$A3),0),"") -> 90083589000
A4: =Data!A4 -> Nakit ve Nakit Benzerleri | B4: =IFERROR(HLOOKUP(B$1,Data!$1:$149,ROW(Bilanço!$A4),0),"") -> 1219355000 | C4: =IFERROR(HLOOKUP(C$1,Data!$1:$149,ROW(Bilanço!$A4),0),"") -> 2956000000 | D4: =IFERROR(HLOOKUP(D$1,Data!$1:$149,ROW(Bilanço!$A4),0),"") -> 3532368000 | E4: =IFERROR(HLOOKUP(E$1,Data!$1:$149,ROW(Bilanço!$A4),0),"") -> 3835520000 | F4: =IFERROR(HLOOKUP(F$1,Data!$1:$149,ROW(Bilanço!$A4),0),"") -> 3367634000 | G4: =IFERROR(HLOOKUP(G$1,Data!$1:$149,ROW(Bilanço!$A4),0),"") -> 2762136000 | H4: =IFERROR(HLOOKUP(H$1,Data!$1:$149,ROW(Bilanço!$A4),0),"") -> 2862609000 | I4: =IFERROR(HLOOKUP(I$1,Data!$1:$149,ROW(Bilanço!$A4),0),"") -> 3004834000 | ... X4: =IFERROR(HLOOKUP(X$1,Data!$1:$149,ROW(Bilanço!$A4),0),"") -> 29570256000
A5: =Data!A5 -> Finansal Yatırımlar | B5: =IFERROR(HLOOKUP(B$1,Data!$1:$149,ROW(Bilanço!$A5),0),"") -> 3820230000 | C5: =IFERROR(HLOOKUP(C$1,Data!$1:$149,ROW(Bilanço!$A5),0),"") -> 3605728000 | D5: =IFERROR(HLOOKUP(D$1,Data!$1:$149,ROW(Bilanço!$A5),0),"") -> 2374641000 | E5: =IFERROR(HLOOKUP(E$1,Data!$1:$149,ROW(Bilanço!$A5),0),"") -> 3639474000 | F5: =IFERROR(HLOOKUP(F$1,Data!$1:$149,ROW(Bilanço!$A5),0),"") -> 5597490000 | G5: =IFERROR(HLOOKUP(G$1,Data!$1:$149,ROW(Bilanço!$A5),0),"") -> 6005890000 | H5: =IFERROR(HLOOKUP(H$1,Data!$1:$149,ROW(Bilanço!$A5),0),"") -> 4277960000 | I5: =IFERROR(HLOOKUP(I$1,Data!$1:$149,ROW(Bilanço!$A5),0),"") -> 6414869000 | ... X5: =IFERROR(HLOOKUP(X$1,Data!$1:$149,ROW(Bilanço!$A5),0),"") -> 6245000
A6: =Data!A6 -> Ticari Alacaklar | B6: =IFERROR(HLOOKUP(B$1,Data!$1:$149,ROW(Bilanço!$A6),0),"") -> 2726899000 | C6: =IFERROR(HLOOKUP(C$1,Data!$1:$149,ROW(Bilanço!$A6),0),"") -> 2577242000 | D6: =IFERROR(HLOOKUP(D$1,Data!$1:$149,ROW(Bilanço!$A6),0),"") -> 2889558000 | E6: =IFERROR(HLOOKUP(E$1,Data!$1:$149,ROW(Bilanço!$A6),0),"") -> 3092000000 | F6: =IFERROR(HLOOKUP(F$1,Data!$1:$149,ROW(Bilanço!$A6),0),"") -> 3256697000 | G6: =IFERROR(HLOOKUP(G$1,Data!$1:$149,ROW(Bilanço!$A6),0),"") -> 3284920000 | H6: =IFERROR(HLOOKUP(H$1,Data!$1:$149,ROW(Bilanço!$A6),0),"") -> 3642113000 | I6: =IFERROR(HLOOKUP(I$1,Data!$1:$149,ROW(Bilanço!$A6),0),"") -> 4687911000 | ... X6: =IFERROR(HLOOKUP(X$1,Data!$1:$149,ROW(Bilanço!$A6),0),"") -> 29618330000
A7: =Data!A7 -> Finans Sektörü Faaliyetlerinden Alacaklar | B7: =IFERROR(HLOOKUP(B$1,Data!$1:$149,ROW(Bilanço!$A7),0),"") -> 0 | C7: =IFERROR(HLOOKUP(C$1,Data!$1:$149,ROW(Bilanço!$A7),0),"") -> 0 | D7: =IFERROR(HLOOKUP(D$1,Data!$1:$149,ROW(Bilanço!$A7),0),"") -> 0 | E7: =IFERROR(HLOOKUP(E$1,Data!$1:$149,ROW(Bilanço!$A7),0),"") -> 0 | F7: =IFERROR(HLOOKUP(F$1,Data!$1:$149,ROW(Bilanço!$A7),0),"") -> 0 | G7: =IFERROR(HLOOKUP(G$1,Data!$1:$149,ROW(Bilanço!$A7),0),"") -> 0 | H7: =IFERROR(HLOOKUP(H$1,Data!$1:$149,ROW(Bilanço!$A7),0),"") -> 0 | I7: =IFERROR(HLOOKUP(I$1,Data!$1:$149,ROW(Bilanço!$A7),0),"") -> 0 | ... X7: =IFERROR(HLOOKUP(X$1,Data!$1:$149,ROW(Bilanço!$A7),0),"") -> 0
A8: =Data!A8 -> Diğer Alacaklar | B8: =IFERROR(HLOOKUP(B$1,Data!$1:$149,ROW(Bilanço!$A8),0),"") -> 180177000 | C8: =IFERROR(HLOOKUP(C$1,Data!$1:$149,ROW(Bilanço!$A8),0),"") -> 158926000 | D8: =IFERROR(HLOOKUP(D$1,Data!$1:$149,ROW(Bilanço!$A8),0),"") -> 1870764000 | E8: =IFERROR(HLOOKUP(E$1,Data!$1:$149,ROW(Bilanço!$A8),0),"") -> 2214736000 | F8: =IFERROR(HLOOKUP(F$1,Data!$1:$149,ROW(Bilanço!$A8),0),"") -> 1974940000 | G8: =IFERROR(HLOOKUP(G$1,Data!$1:$149,ROW(Bilanço!$A8),0),"") -> 2137532000 | H8: =IFERROR(HLOOKUP(H$1,Data!$1:$149,ROW(Bilanço!$A8),0),"") -> 609152000 | I8: =IFERROR(HLOOKUP(I$1,Data!$1:$149,ROW(Bilanço!$A8),0),"") -> 614402000 | ... X8: =IFERROR(HLOOKUP(X$1,Data!$1:$149,ROW(Bilanço!$A8),0),"") -> 2530647000
A9: =Data!A9 -> Müşteri Sözleşmelerinden Doğan Varlıklar | B9: =IFERROR(HLOOKUP(B$1,Data!$1:$149,ROW(Bilanço!$A9),0),"") -> 0 | C9: =IFERROR(HLOOKUP(C$1,Data!$1:$149,ROW(Bilanço!$A9),0),"") -> 0 | D9: =IFERROR(HLOOKUP(D$1,Data!$1:$149,ROW(Bilanço!$A9),0),"") -> 0 | E9: =IFERROR(HLOOKUP(E$1,Data!$1:$149,ROW(Bilanço!$A9),0),"") -> 0 | F9: =IFERROR(HLOOKUP(F$1,Data!$1:$149,ROW(Bilanço!$A9),0),"") -> 0 | G9: =IFERROR(HLOOKUP(G$1,Data!$1:$149,ROW(Bilanço!$A9),0),"") -> 0 | H9: =IFERROR(HLOOKUP(H$1,Data!$1:$149,ROW(Bilanço!$A9),0),"") -> 0 | I9: =IFERROR(HLOOKUP(I$1,Data!$1:$149,ROW(Bilanço!$A9),0),"") -> 0 | ... X9: =IFERROR(HLOOKUP(X$1,Data!$1:$149,ROW(Bilanço!$A9),0),"") -> 0
A10: =Data!A10 -> Stoklar | B10: =IFERROR(HLOOKUP(B$1,Data!$1:$149,ROW(Bilanço!$A10),0),"") -> 671929000 | C10: =IFERROR(HLOOKUP(C$1,Data!$1:$149,ROW(Bilanço!$A10),0),"") -> 804703000 | D10: =IFERROR(HLOOKUP(D$1,Data!$1:$149,ROW(Bilanço!$A10),0),"") -> 897909000 | E10: =IFERROR(HLOOKUP(E$1,Data!$1:$149,ROW(Bilanço!$A10),0),"") -> 1695858000 | F10: =IFERROR(HLOOKUP(F$1,Data!$1:$149,ROW(Bilanço!$A10),0),"") -> 928950000 | G10: =IFERROR(HLOOKUP(G$1,Data!$1:$149,ROW(Bilanço!$A10),0),"") -> 961339000 | H10: =IFERROR(HLOOKUP(H$1,Data!$1:$149,ROW(Bilanço!$A10),0),"") -> 2028702000 | I10: =IFERROR(HLOOKUP(I$1,Data!$1:$149,ROW(Bilanço!$A10),0),"") -> 3218231000 | ... X10: =IFERROR(HLOOKUP(X$1,Data!$1:$149,ROW(Bilanço!$A10),0),"") -> 23046205000
A11: =Data!A11 -> Canlı Varlıklar | B11: =IFERROR(HLOOKUP(B$1,Data!$1:$149,ROW(Bilanço!$A11),0),"") -> 0 | C11: =IFERROR(HLOOKUP(C$1,Data!$1:$149,ROW(Bilanço!$A11),0),"") -> 0 | D11: =IFERROR(HLOOKUP(D$1,Data!$1:$149,ROW(Bilanço!$A11),0),"") -> 0 | E11: =IFERROR(HLOOKUP(E$1,Data!$1:$149,ROW(Bilanço!$A11),0),"") -> 0 | F11: =IFERROR(HLOOKUP(F$1,Data!$1:$149,ROW(Bilanço!$A11),0),"") -> 0 | G11: =IFERROR(HLOOKUP(G$1,Data!$1:$149,ROW(Bilanço!$A11),0),"") -> 0 | H11: =IFERROR(HLOOKUP(H$1,Data!$1:$149,ROW(Bilanço!$A11),0),"") -> 0 | I11: =IFERROR(HLOOKUP(I$1,Data!$1:$149,ROW(Bilanço!$A11),0),"") -> 0 | ... X11: =IFERROR(HLOOKUP(X$1,Data!$1:$149,ROW(Bilanço!$A11),0),"") -> 0
A12: =Data!A12 -> Diğer Dönen Varlıklar | B12: =IFERROR(HLOOKUP(B$1,Data!$1:$149,ROW(Bilanço!$A12),0),"") -> 605936000 | C12: =IFERROR(HLOOKUP(C$1,Data!$1:$149,ROW(Bilanço!$A12),0),"") -> 196216000 | D12: =IFERROR(HLOOKUP(D$1,Data!$1:$149,ROW(Bilanço!$A12),0),"") -> 362495000 | E12: =IFERROR(HLOOKUP(E$1,Data!$1:$149,ROW(Bilanço!$A12),0),"") -> 223531000 | F12: =IFERROR(HLOOKUP(F$1,Data!$1:$149,ROW(Bilanço!$A12),0),"") -> 239685000 | G12: =IFERROR(HLOOKUP(G$1,Data!$1:$149,ROW(Bilanço!$A12),0),"") -> 253418000 | H12: =IFERROR(HLOOKUP(H$1,Data!$1:$149,ROW(Bilanço!$A12),0),"") -> 432373000 | I12: =IFERROR(HLOOKUP(I$1,Data!$1:$149,ROW(Bilanço!$A12),0),"") -> 824693000 | ... X12: =IFERROR(HLOOKUP(X$1,Data!$1:$149,ROW(Bilanço!$A12),0),"") -> 5311906000
A13: =Data!A13 -> (Ara Toplam) | B13: =IFERROR(HLOOKUP(B$1,Data!$1:$149,ROW(Bilanço!$A13),0),"") -> 9224526000 | C13: =IFERROR(HLOOKUP(C$1,Data!$1:$149,ROW(Bilanço!$A13),0),"") -> 10298815000 | D13: =IFERROR(HLOOKUP(D$1,Data!$1:$149,ROW(Bilanço!$A13),0),"") -> 11927735000 | E13: =IFERROR(HLOOKUP(E$1,Data!$1:$149,ROW(Bilanço!$A13),0),"") -> 14701119000 | F13: =IFERROR(HLOOKUP(F$1,Data!$1:$149,ROW(Bilanço!$A13),0),"") -> 15365396000 | G13: =IFERROR(HLOOKUP(G$1,Data!$1:$149,ROW(Bilanço!$A13),0),"") -> 15405235000 | H13: =IFERROR(HLOOKUP(H$1,Data!$1:$149,ROW(Bilanço!$A13),0),"") -> 13852909000 | I13: =IFERROR(HLOOKUP(I$1,Data!$1:$149,ROW(Bilanço!$A13),0),"") -> 18764940000 | ... X13: =IFERROR(HLOOKUP(X$1,Data!$1:$149,ROW(Bilanço!$A13),0),"") -> 90083589000
... A149: =Data!A149 -> Dönem Sonu Nakit | B149: =IFERROR(HLOOKUP(B$1,Data!$1:$149,ROW(Bilanço!$A149),0),"") -> 1219355000 | C149: =IFERROR(HLOOKUP(C$1,Data!$1:$149,ROW(Bilanço!$A149),0),"") -> 2956000000 | D149: =IFERROR(HLOOKUP(D$1,Data!$1:$149,ROW(Bilanço!$A149),0),"") -> 3538025000 | E149: =IFERROR(HLOOKUP(E$1,Data!$1:$149,ROW(Bilanço!$A149),0),"") -> 3835520000 | F149: =IFERROR(HLOOKUP(F$1,Data!$1:$149,ROW(Bilanço!$A149),0),"") -> 3394555000 | G149: =IFERROR(HLOOKUP(G$1,Data!$1:$149,ROW(Bilanço!$A149),0),"") -> 3049937000 | H149: =IFERROR(HLOOKUP(H$1,Data!$1:$149,ROW(Bilanço!$A149),0),"") -> 2862609000 | I149: =IFERROR(HLOOKUP(I$1,Data!$1:$149,ROW(Bilanço!$A149),0),"") -> 3004834000 | ... X149: =IFERROR(HLOOKUP(X$1,Data!$1:$149,ROW(Bilanço!$A149),0),"") -> 29570256000
A150: FAVÖK | B150: =IFERROR(B83+(B84+B85+B86)+B116,"") -> 415167000 | C150: =IFERROR(C83+(C84+C85+C86)+C116,"") -> 794946000 | D150: =IFERROR(D83+(D84+D85+D86)+D116,"") -> 1374511000 | E150: =IFERROR(E83+(E84+E85+E86)+E116,"") -> 1922060000 | F150: =IFERROR(F83+(F84+F85+F86)+F116,"") -> 546384000 | G150: =IFERROR(G83+(G84+G85+G86)+G116,"") -> 993008000 | H150: =IFERROR(H83+(H84+H85+H86)+H116,"") -> 1495751000 | I150: =IFERROR(I83+(I84+I85+I86)+I116,"") -> 2328359000 | ... X150: =IFERROR(X83+(X84+X85+X86)+X116,"") -> 14382507000
A151: HBK | B151: =IFERROR(B111/B62,"") -> -0.28740351 | C151: =IFERROR(C111/C62,"") -> 1.187576 | D151: =IFERROR(D111/D62,"") -> 1.9927865 | E151: =IFERROR(E111/E62,"") -> 3.1619708 | F151: =IFERROR(F111/F62,"") -> 1.2606637 | G151: =IFERROR(G111/G62,"") -> 1.9070088 | H151: =IFERROR(H111/H62,"") -> 1.914193 | I151: =IFERROR(I111/I62,"") -> -1.3576959 | ... X151: =IFERROR(X111/X62,"") -> 12.439249
C152: =RIGHT(C153,2) -> /6 | F152: =RIGHT(F153,2) -> /3 | X152: =IFERROR(HLOOKUP(X$1,Data!$1:$149,ROW(Bilanço!$A152),0),"")
A153: Net İşletme Sermayesi Analizi | B153: =B2 -> 2020/3 | C153: =C2 -> 2020/6 | D153: =D2 -> 2020/9 | E153: =E2 -> 2020/12 | F153: =F2 -> 2021/3 | G153: =G2 -> 2021/6 | H153: =H2 -> 2021/9 | I153: =I2 -> 2021/12 | ... X153: =X2 -> 2025/9
A154: Ortalama Ticari Alacaklar | F154: =AVERAGE($E$6,F6) -> 3174348500 | G154: =AVERAGE($E$6,G6) -> 3188460000 | H154: =AVERAGE($E$6,H6) -> 3367056500 | I154: =AVERAGE($E$6,I6) -> 3889955500 | J154: =AVERAGE($I$6,J6) -> 5271992000 | K154: =AVERAGE($I$6,K6) -> 5238766000 | L154: =AVERAGE($I$6,L6) -> 5865299500 | M154: =AVERAGE($I$6,M6) -> 8430947000 | N154: =AVERAGE($M$6,N6) -> 10849431000 | O154: =AVERAGE($M$6,O6) -> 11033371500 | P154: =AVERAGE($M$6,P6) -> 11533570000 | Q154: =AVERAGE($M$6,Q6) -> 14797948000 | R154: =AVERAGE($Q$6,R6) -> 16889378500 | S154: =AVERAGE($Q$6,S6) -> 16276557000 | T154: =AVERAGE($Q$6,T6) -> 17931635000 | U154: =AVERAGE($Q$6,U6) -> 2.2445299e+10 | V154: =AVERAGE($U$6,V6) -> 2.7423816e+10 | W154: =AVERAGE($U$6,W6) -> 2.6995354e+10 | X154: =AVERAGE($U$6,X6) -> 2.8543507e+10
A155: KDV Oranı | F155: 0.2 | G155: 0.2 | H155: 0.2 | I155: 0.2 | J155: 0.2 | K155: 0.2 | L155: 0.2 | M155: 0.2 | N155: 0.2 | O155: 0.2 | P155: 0.2 | Q155: 0.2 | R155: 0.2 | S155: 0.2 | T155: 0.2 | U155: 0.2 | V155: 0.2 | W155: 0.2 | X155: 0.2
A156: KDV Hariç Ortalama Ticari Alacak | F156: =F154/(1+F155) -> 2.6452904e+09 | G156: =G154/(1+G155) -> 2657050000 | H156: =H154/(1+H155) -> 2.8058804e+09 | I156: =I154/(1+I155) -> 3.2416296e+09 | J156: =J154/(1+J155) -> 4.3933267e+09 | K156: =K154/(1+K155) -> 4.3656383e+09 | L156: =L154/(1+L155) -> 4.8877496e+09 | M156: =M154/(1+M155) -> 7.0257892e+09 | ... X156: =X154/(1+X155) -> 2.3786256e+10
A157: Ticari Alacak Devir Hızı | F157: {=IFERROR(F74/F156,0)*_xlfn.IFS(RIGHT(F153,2)="/3",12/3,RIGHT(F153,2)="/6",12/6,RIGHT(F153,2)="/9",12/9,RIGHT(F153,2)="12",1)} -> 4.2093783 | G157: {=IFERROR(G74/G156,0)*_xlfn.IFS(RIGHT(G153,2)="/3",12/3,RIGHT(G153,2)="/6",12/6,RIGHT(G153,2)="/9",12/9,RIGHT(G153,2)="12",1)} -> 4.0968924 | H157: {=IFERROR(H74/H156,0)*_xlfn.IFS(RIGHT(H153,2)="/3",12/3,RIGHT(H153,2)="/6",12/6,RIGHT(H153,2)="/9",12/9,RIGHT(H153,2)="12",1)} -> 4.0006252 | I157: {=IFERROR(I74/I156,0)*_xlfn.IFS(RIGHT(I153,2)="/3",12/3,RIGHT(I153,2)="/6",12/6,RIGHT(I153,2)="/9",12/9,RIGHT(I153,2)="12",1)} -> 3.8675239 | J157: {=IFERROR(J74/J156,0)*_xlfn.IFS(RIGHT(J153,2)="/3",12/3,RIGHT(J153,2)="/6",12/6,RIGHT(J153,2)="/9",12/9,RIGHT(J153,2)="12",1)} -> 5.3590534 | K157: {=IFERROR(K74/K156,0)*_xlfn.IFS(RIGHT(K153,2)="/3",12/3,RIGHT(K153,2)="/6",12/6,RIGHT(K153,2)="/9",12/9,RIGHT(K153,2)="12",1)} -> 5.4411562 | L157: {=IFERROR(L74/L156,0)*_xlfn.IFS(RIGHT(L153,2)="/3",12/3,RIGHT(L153,2)="/6",12/6,RIGHT(L153,2)="/9",12/9,RIGHT(L153,2)="12",1)} -> 5.2318229 | M157: {=IFERROR(M74/M156,0)*_xlfn.IFS(RIGHT(M153,2)="/3",12/3,RIGHT(M153,2)="/6",12/6,RIGHT(M153,2)="/9",12/9,RIGHT(M153,2)="12",1)} -> 7.3986291 | ... X157: {=IFERROR(X74/X156,0)*_xlfn.IFS(RIGHT(X153,2)="/3",12/3,RIGHT(X153,2)="/6",12/6,RIGHT(X153,2)="/9",12/9,RIGHT(X153,2)="12",1)} -> 4.5362843
A158: Ticari Alacak Devir Süresi (Gün) | F158: =IFERROR(365/F157,0) -> 86.711143 | G158: =IFERROR(365/G157,0) -> 89.091917 | H158: =IFERROR(365/H157,0) -> 91.235739 | I158: =IFERROR(365/I157,0) -> 94.375628 | J158: =IFERROR(365/J157,0) -> 68.109044 | K158: =IFERROR(365/K157,0) -> 67.081331 | L158: =IFERROR(365/L157,0) -> 69.765359 | M158: =IFERROR(365/M157,0) -> 49.333464 | ... X158: =IFERROR(365/X157,0) -> 80.462329
A160: Ortalama Stoklar | F160: =AVERAGE($E$10,F10) -> 1312404000 | G160: =AVERAGE($E$10,G10) -> 1328598500 | H160: =AVERAGE($E$10,H10) -> 1862280000 | I160: =AVERAGE($E$10,I10) -> 2457044500 | J160: =AVERAGE($I$10,J10) -> 3481562000 | K160: =AVERAGE($I$10,K10) -> 3749000000 | L160: =AVERAGE($I$10,L10) -> 4310183000 | M160: =AVERAGE($I$10,M10) -> 5867307500 | N160: =AVERAGE($M$10,N10) -> 7018505500 | O160: =AVERAGE($M$10,O10) -> 7535771500 | P160: =AVERAGE($M$10,P10) -> 7590364500 | Q160: =AVERAGE($M$10,Q10) -> 10315797000 | R160: =AVERAGE($Q$10,R10) -> 10557132500 | S160: =AVERAGE($Q$10,S10) -> 11265047500 | T160: =AVERAGE($Q$10,T10) -> 11556971500 | U160: =AVERAGE($Q$10,U10) -> 13477175902 | V160: =AVERAGE($U$10,V10) -> 16969091902 | W160: =AVERAGE($U$10,W10) -> 19205126902 | X160: =AVERAGE($U$10,X10) -> 18942673402
A161: Stok Devir Hızı | F161: {=IFERROR(-F75/F160,0)*_xlfn.IFS(RIGHT(F153,2)="/3",12/3,RIGHT(F153,2)="/6",12/6,RIGHT(F153,2)="/9",12/9,RIGHT(F153,2)="12",1)} -> 5.8561815 | G161: {=IFERROR(-G75/G160,0)*_xlfn.IFS(RIGHT(G153,2)="/3",12/3,RIGHT(G153,2)="/6",12/6,RIGHT(G153,2)="/9",12/9,RIGHT(G153,2)="12",1)} -> 5.8243751 | H161: {=IFERROR(-H75/H160,0)*_xlfn.IFS(RIGHT(H153,2)="/3",12/3,RIGHT(H153,2)="/6",12/6,RIGHT(H153,2)="/9",12/9,RIGHT(H153,2)="12",1)} -> 4.3252193 | I161: {=IFERROR(-I75/I160,0)*_xlfn.IFS(RIGHT(I153,2)="/3",12/3,RIGHT(I153,2)="/6",12/6,RIGHT(I153,2)="/9",12/9,RIGHT(I153,2)="12",1)} -> 3.6322765 | J161: {=IFERROR(-J75/J160,0)*_xlfn.IFS(RIGHT(J153,2)="/3",12/3,RIGHT(J153,2)="/6",12/6,RIGHT(J153,2)="/9",12/9,RIGHT(J153,2)="12",1)} -> 4.6380653 | K161: {=IFERROR(-K75/K160,0)*_xlfn.IFS(RIGHT(K153,2)="/3",12/3,RIGHT(K153,2)="/6",12/6,RIGHT(K153,2)="/9",12/9,RIGHT(K153,2)="12",1)} -> 4.4439904 | L161: {=IFERROR(-L75/L160,0)*_xlfn.IFS(RIGHT(L153,2)="/3",12/3,RIGHT(L153,2)="/6",12/6,RIGHT(L153,2)="/9",12/9,RIGHT(L153,2)="12",1)} -> 4.2105491 | M161: {=IFERROR(-M75/M160,0)*_xlfn.IFS(RIGHT(M153,2)="/3",12/3,RIGHT(M153,2)="/6",12/6,RIGHT(M153,2)="/9",12/9,RIGHT(M153,2)="12",1)} -> 6.9287349 | ... X161: {=IFERROR(-X75/X160,0)*_xlfn.IFS(RIGHT(X153,2)="/3",12/3,RIGHT(X153,2)="/6",12/6,RIGHT(X153,2)="/9",12/9,RIGHT(X153,2)="12",1)} -> 3.9747247
A162: Stok Devir Süresi (Gün) | F162: =IFERROR(365/F161,0) -> 62.327303 | G162: =IFERROR(365/G161,0) -> 62.667667 | H162: =IFERROR(365/H161,0) -> 84.388785 | I162: =IFERROR(365/I161,0) -> 100.48794 | J162: =IFERROR(365/J161,0) -> 78.696606 | K162: =IFERROR(365/K161,0) -> 82.133391 | L162: =IFERROR(365/L161,0) -> 86.68703 | M162: =IFERROR(365/M161,0) -> 52.67917 | ... X162: =IFERROR(365/X161,0) -> 91.830259
A164: Ortalama Ticari Borçlar | F164: =AVERAGE($E$36,F36) -> 1346308000 | G164: =AVERAGE($E$36,G36) -> 1346154500 | H164: =AVERAGE($E$36,H36) -> 1323291000 | I164: =AVERAGE($E$36,I36) -> 1772915500 | J164: =AVERAGE($I$36,J36) -> 2610007500 | K164: =AVERAGE($I$36,K36) -> 2770230000 | L164: =AVERAGE($I$36,L36) -> 3034239000 | M164: =AVERAGE($I$36,M36) -> 4563531000 | N164: =AVERAGE($M$36,N36) -> 5363660500 | O164: =AVERAGE($M$36,O36) -> 5642194000 | P164: =AVERAGE($M$36,P36) -> 6167666500 | Q164: =AVERAGE($M$36,Q36) -> 8940022000 | R164: =AVERAGE($Q$36,R36) -> 8984942000 | S164: =AVERAGE($Q$36,S36) -> 9138154000 | T164: =AVERAGE($Q$36,T36) -> 9027763000 | U164: =AVERAGE($Q$36,U36) -> 1.1951563e+10 | V164: =AVERAGE($U$36,V36) -> 1.1370406e+10 | W164: =AVERAGE($U$36,W36) -> 1.1454714e+10 | X164: =AVERAGE($U$36,X36) -> 1.1302981e+10
A165: KDV Oranı | F165: 0.2 | G165: 0.2 | H165: 0.2 | I165: 0.2 | J165: 0.2 | K165: 0.2 | L165: 0.2 | M165: 0.2 | N165: 0.2 | O165: 0.2 | P165: 0.2 | Q165: 0.2 | R165: 0.2 | S165: 0.2 | T165: 0.2 | U165: 0.2 | V165: 0.2 | W165: 0.2 | X165: 0.2
A166: KDV Hariç Ortalama Ticari Borçlar | F166: =F164/(1+F165) -> 1.1219233e+09 | G166: =G164/(1+G165) -> 1.1217954e+09 | H166: =H164/(1+H165) -> 1102742500 | I166: =I164/(1+I165) -> 1.4774296e+09 | J166: =J164/(1+J165) -> 2175006250 | K166: =K164/(1+K165) -> 2308525000 | L166: =L164/(1+L165) -> 2528532500 | M166: =M164/(1+M165) -> 3802942500 | ... X166: =X164/(1+X165) -> 9.419151e+09
A167: Ticari Borç Devir Hızı | F167: {=IFERROR(-1*(F75+SUM(F84:F86))/F166*_xlfn.IFS(RIGHT(F153,2)="/3",12/3,RIGHT(F153,2)="/6",12/6,RIGHT(F153,2)="/9",12/9,RIGHT(F153,2)="12",1),"")} -> 8.1657808 | G167: {=IFERROR(-1*(G75+SUM(G84:G86))/G166*_xlfn.IFS(RIGHT(G153,2)="/3",12/3,RIGHT(G153,2)="/6",12/6,RIGHT(G153,2)="/9",12/9,RIGHT(G153,2)="12",1),"")} -> 8.1279098 | H167: {=IFERROR(-1*(H75+SUM(H84:H86))/H166*_xlfn.IFS(RIGHT(H153,2)="/3",12/3,RIGHT(H153,2)="/6",12/6,RIGHT(H153,2)="/9",12/9,RIGHT(H153,2)="12",1),"")} -> 8.5746159 | I167: {=IFERROR(-1*(I75+SUM(I84:I86))/I166*_xlfn.IFS(RIGHT(I153,2)="/3",12/3,RIGHT(I153,2)="/6",12/6,RIGHT(I153,2)="/9",12/9,RIGHT(I153,2)="12",1),"")} -> 7.065467 | J167: {=IFERROR(-1*(J75+SUM(J84:J86))/J166*_xlfn.IFS(RIGHT(J153,2)="/3",12/3,RIGHT(J153,2)="/6",12/6,RIGHT(J153,2)="/9",12/9,RIGHT(J153,2)="12",1),"")} -> 8.679438 | K167: {=IFERROR(-1*(K75+SUM(K84:K86))/K166*_xlfn.IFS(RIGHT(K153,2)="/3",12/3,RIGHT(K153,2)="/6",12/6,RIGHT(K153,2)="/9",12/9,RIGHT(K153,2)="12",1),"")} -> 8.3686492 | L167: {=IFERROR(-1*(L75+SUM(L84:L86))/L166*_xlfn.IFS(RIGHT(L153,2)="/3",12/3,RIGHT(L153,2)="/6",12/6,RIGHT(L153,2)="/9",12/9,RIGHT(L153,2)="12",1),"")} -> 8.3297554 | M167: {=IFERROR(-1*(M75+SUM(M84:M86))/M166*_xlfn.IFS(RIGHT(M153,2)="/3",12/3,RIGHT(M153,2)="/6",12/6,RIGHT(M153,2)="/9",12/9,RIGHT(M153,2)="12",1),"")} -> 12.213193 | ... X167: {=IFERROR(-1*(X75+SUM(X84:X86))/X166*_xlfn.IFS(RIGHT(X153,2)="/3",12/3,RIGHT(X153,2)="/6",12/6,RIGHT(X153,2)="/9",12/9,RIGHT(X153,2)="12",1),"")} -> 9.670283
A168: Ticari Borç Devir Süresi (gün) | F168: =IFERROR(365/F167,0) -> 44.698726 | G168: =IFERROR(365/G167,0) -> 44.906994 | H168: =IFERROR(365/H167,0) -> 42.567505 | I168: =IFERROR(365/I167,0) -> 51.659713 | J168: =IFERROR(365/J167,0) -> 42.053414 | K168: =IFERROR(365/K167,0) -> 43.615163 | L168: =IFERROR(365/L167,0) -> 43.818814 | M168: =IFERROR(365/M167,0) -> 29.885714 | ... X168: =IFERROR(365/X167,0) -> 37.7445
A170: Net İşletme Sermayesi İhtiyaç Süresi | F170: =F158+F162-F168 -> 104.33972 | G170: =G158+G162-G168 -> 106.85259 | H170: =H158+H162-H168 -> 133.05702 | I170: =I158+I162-I168 -> 143.20386 | J170: =J158+J162-J168 -> 104.75224 | K170: =K158+K162-K168 -> 105.59956 | L170: =L158+L162-L168 -> 112.63358 | M170: =M158+M162-M168 -> 72.126919 | ... X170: =X158+X162-X168 -> 134.54809
A171: Net İşletme Sermayesi İhtiyacı | F171: {=((-1*(F75+SUM(F84:F86))-F127)*F170/365)*_xlfn.IFS(RIGHT(F153,2)="/3",12/3,RIGHT(F153,2)="/6",12/6,RIGHT(F153,2)="/9",12/9,RIGHT(F153,2)="12",1)} -> 2.5583219e+09 | G171: {=((-1*(G75+SUM(G84:G86))-G127)*G170/365)*_xlfn.IFS(RIGHT(G153,2)="/3",12/3,RIGHT(G153,2)="/6",12/6,RIGHT(G153,2)="/9",12/9,RIGHT(G153,2)="12",1)} -> 2.605339e+09 | H171: {=((-1*(H75+SUM(H84:H86))-H127)*H170/365)*_xlfn.IFS(RIGHT(H153,2)="/3",12/3,RIGHT(H153,2)="/6",12/6,RIGHT(H153,2)="/9",12/9,RIGHT(H153,2)="12",1)} -> 3.3650453e+09 | I171: {=((-1*(I75+SUM(I84:I86))-I127)*I170/365)*_xlfn.IFS(RIGHT(I153,2)="/3",12/3,RIGHT(I153,2)="/6",12/6,RIGHT(I153,2)="/9",12/9,RIGHT(I153,2)="12",1)} -> 4.0052829e+09 | J171: {=((-1*(J75+SUM(J84:J86))-J127)*J170/365)*_xlfn.IFS(RIGHT(J153,2)="/3",12/3,RIGHT(J153,2)="/6",12/6,RIGHT(J153,2)="/9",12/9,RIGHT(J153,2)="12",1)} -> 5.3281786e+09 | K171: {=((-1*(K75+SUM(K84:K86))-K127)*K170/365)*_xlfn.IFS(RIGHT(K153,2)="/3",12/3,RIGHT(K153,2)="/6",12/6,RIGHT(K153,2)="/9",12/9,RIGHT(K153,2)="12",1)} -> 5.4958431e+09 | L171: {=((-1*(L75+SUM(L84:L86))-L127)*L170/365)*_xlfn.IFS(RIGHT(L153,2)="/3",12/3,RIGHT(L153,2)="/6",12/6,RIGHT(L153,2)="/9",12/9,RIGHT(L153,2)="12",1)} -> 6.3964079e+09 | M171: {=((-1*(M75+SUM(M84:M86))-M127)*M170/365)*_xlfn.IFS(RIGHT(M153,2)="/3",12/3,RIGHT(M153,2)="/6",12/6,RIGHT(M153,2)="/9",12/9,RIGHT(M153,2)="12",1)} -> 8.947355e+09 | ... X171: {=((-1*(X75+SUM(X84:X86))-X127)*X170/365)*_xlfn.IFS(RIGHT(X153,2)="/3",12/3,RIGHT(X153,2)="/6",12/6,RIGHT(X153,2)="/9",12/9,RIGHT(X153,2)="12",1)} -> 3.2706076e+10
A172: Mevcut Net İşletme Sermayesi | F172: =F3-F33 -> 12399791000 | G172: =G3-G33 -> 12507296000 | H172: =H3-H33 -> 9643043000 | I172: =I3-I33 -> 12630718000 | J172: =J3-J33 -> 13697328000 | K172: =K3-K33 -> 7395441000 | L172: =L3-L33 -> 8535038000 | M172: =M3-M33 -> 13947436000 | ... X172: =X3-X33 -> 29248106000
F173: =F172-F171 -> 9.8414691e+09 | G173: =G172-G171 -> 9.901957e+09 | H173: =H172-H171 -> 6.2779977e+09 | I173: =I172-I171 -> 8.6254351e+09 | J173: =J172-J171 -> 8.3691494e+09 | K173: =K172-K171 -> 1.8995979e+09 | L173: =L172-L171 -> 2.1386301e+09 | M173: =M172-M171 -> 5.000081e+09 | ... X173: =X172-X171 -> -3.45797e+09
C176: {=INDIRECT(ADDRESS(36,2))} -> 1163014000

Sheet Çeyreklik
B1: =IF(Bilanço!B2="2022/3",COUNT(Data!$1:$1)+1,COUNT(Data!$1:$1)) -> 23 | C1: =($B$1+1)-COLUMN(B1) -> 22 | D1: =($B$1+1)-COLUMN(C1) -> 21 | E1: =($B$1+1)-COLUMN(D1) -> 20 | F1: =($B$1+1)-COLUMN(E1) -> 19 | G1: =($B$1+1)-COLUMN(F1) -> 18 | H1: =($B$1+1)-COLUMN(G1) -> 17 | I1: =($B$1+1)-COLUMN(H1) -> 16 | J1: =($B$1+1)-COLUMN(I1) -> 15 | ... W1: =($B$1+1)-COLUMN(V1) -> 2
A2: =Data!A2 -> Bilanço | B2: =IFERROR(HLOOKUP(B$1,Data!$1:$149,ROW(Bilanço!$A2),0),"") -> 2020/6 | C2: =IFERROR(HLOOKUP(C$1,Data!$1:$149,ROW(Bilanço!$A2),0),"") -> 2020/9 | D2: =IFERROR(HLOOKUP(D$1,Data!$1:$149,ROW(Bilanço!$A2),0),"") -> 2020/12 | E2: =IFERROR(HLOOKUP(E$1,Data!$1:$149,ROW(Bilanço!$A2),0),"") -> 2021/3 | F2: =IFERROR(HLOOKUP(F$1,Data!$1:$149,ROW(Bilanço!$A2),0),"") -> 2021/6 | G2: =IFERROR(HLOOKUP(G$1,Data!$1:$149,ROW(Bilanço!$A2),0),"") -> 2021/9 | H2: =IFERROR(HLOOKUP(H$1,Data!$1:$149,ROW(Bilanço!$A2),0),"") -> 2021/12 | I2: =IFERROR(HLOOKUP(I$1,Data!$1:$149,ROW(Bilanço!$A2),0),"") -> 2022/3 | ... W2: =IFERROR(HLOOKUP(W$1,Data!$1:$149,ROW(Bilanço!$A2),0),"") -> 2025/9
A3: =Data!A74 -> Satış Gelirleri | B3: =IFERROR(IF($B$2="2022/3",IF(MID(B$2,6,7)="3",HLOOKUP(B$1,Bilanço!$1:$151,MATCH(Çeyreklik!$A3,Bilanço!$A:$A,0),0),HLOOKUP(B$1,Bilanço!$1:$151,MATCH(Çeyreklik!$A3,Bilanço!$A:$A,0),0)-HLOOKUP(A$1,Bilanço!$1:$151,MATCH(Çeyreklik!$A3,Bilanço!$A:$A,0),0)),IF(MID(B$2,6,7)="3",HLOOKUP(B$1,Bilanço!$1:$151,MATCH(Çeyreklik!$A3,Bilanço!$A:$A,0),0),HLOOKUP(B$1,Bilanço!$1:$151,MATCH(Çeyreklik!$A3,Bilanço!$A:$A,0),0)-HLOOKUP(Bilanço!$B$1,Bilanço!$1:$151,MATCH(Çeyreklik!$A3,Bilanço!$A:$A,0),0))),"") -> 2144641000 | C3: =IFERROR(IF(MID(C$2,6,7)="3",HLOOKUP(C$1,Bilanço!$1:$151,MATCH(Çeyreklik!$A3,Bilanço!$A:$A,0),0),HLOOKUP(C$1,Bilanço!$1:$151,MATCH(Çeyreklik!$A3,Bilanço!$A:$A,0),0)-HLOOKUP(B$1,Bilanço!$1:$151,MATCH(Çeyreklik!$A3,Bilanço!$A:$A,0),0)),"") -> 2455845000 | D3: =IFERROR(IF(MID(D$2,6,7)="3",HLOOKUP(D$1,Bilanço!$1:$151,MATCH(Çeyreklik!$A3,Bilanço!$A:$A,0),0),HLOOKUP(D$1,Bilanço!$1:$151,MATCH(Çeyreklik!$A3,Bilanço!$A:$A,0),0)-HLOOKUP(C$1,Bilanço!$1:$151,MATCH(Çeyreklik!$A3,Bilanço!$A:$A,0),0)),"") -> 2739018000 | E3: =IFERROR(IF(MID(E$2,6,7)="3",HLOOKUP(E$1,Bilanço!$1:$151,MATCH(Çeyreklik!$A3,Bilanço!$A:$A,0),0),HLOOKUP(E$1,Bilanço!$1:$151,MATCH(Çeyreklik!$A3,Bilanço!$A:$A,0),0)-HLOOKUP(D$1,Bilanço!$1:$151,MATCH(Çeyreklik!$A3,Bilanço!$A:$A,0),0)),"") -> 2783757000 | F3: =IFERROR(IF(MID(F$2,6,7)="3",HLOOKUP(F$1,Bilanço!$1:$151,MATCH(Çeyreklik!$A3,Bilanço!$A:$A,0),0),HLOOKUP(F$1,Bilanço!$1:$151,MATCH(Çeyreklik!$A3,Bilanço!$A:$A,0),0)-HLOOKUP(E$1,Bilanço!$1:$151,MATCH(Çeyreklik!$A3,Bilanço!$A:$A,0),0)),"") -> 2659067000 | G3: =IFERROR(IF(MID(G$2,6,7)="3",HLOOKUP(G$1,Bilanço!$1:$151,MATCH(Çeyreklik!$A3,Bilanço!$A:$A,0),0),HLOOKUP(G$1,Bilanço!$1:$151,MATCH(Çeyreklik!$A3,Bilanço!$A:$A,0),0)-HLOOKUP(F$1,Bilanço!$1:$151,MATCH(Çeyreklik!$A3,Bilanço!$A:$A,0),0)),"") -> 2976133000 | H3: =IFERROR(IF(MID(H$2,6,7)="3",HLOOKUP(H$1,Bilanço!$1:$151,MATCH(Çeyreklik!$A3,Bilanço!$A:$A,0),0),HLOOKUP(H$1,Bilanço!$1:$151,MATCH(Çeyreklik!$A3,Bilanço!$A:$A,0),0)-HLOOKUP(G$1,Bilanço!$1:$151,MATCH(Çeyreklik!$A3,Bilanço!$A:$A,0),0)),"") -> 4118123000 | I3: =IFERROR(IF(MID(I$2,6,7)="3",HLOOKUP(I$1,Bilanço!$1:$151,MATCH(Çeyreklik!$A3,Bilanço!$A:$A,0),0),HLOOKUP(I$1,Bilanço!$1:$151,MATCH(Çeyreklik!$A3,Bilanço!$A:$A,0),0)-HLOOKUP(H$1,Bilanço!$1:$151,MATCH(Çeyreklik!$A3,Bilanço!$A:$A,0),0)),"") -> 5886018000 | J3: =IFERROR(IF(MID(J$2,6,7)="3",HLOOKUP(J$1,Bilanço!$1:$151,MATCH(Çeyreklik!$A3,Bilanço!$A:$A,0),0),HLOOKUP(J$1,Bilanço!$1:$151,MATCH(Çeyreklik!$A3,Bilanço!$A:$A,0),0)-HLOOKUP(I$1,Bilanço!$1:$151,MATCH(Çeyreklik!$A3,Bilanço!$A:$A,0),0)),"") -> 5991042000 | ... W3: =IFERROR(IF(MID(W$2,6,7)="3",HLOOKUP(W$1,Bilanço!$1:$151,MATCH(Çeyreklik!$A3,Bilanço!$A:$A,0),0),HLOOKUP(W$1,Bilanço!$1:$151,MATCH(Çeyreklik!$A3,Bilanço!$A:$A,0),0)-HLOOKUP(V$1,Bilanço!$1:$151,MATCH(Çeyreklik!$A3,Bilanço!$A:$A,0),0)),"") -> 29286362000
A4: =Data!A75 -> Satışların Maliyeti (-) | B4: =IFERROR(IF($B$2="2022/3",IF(MID(B$2,6,7)="3",HLOOKUP(B$1,Bilanço!$1:$151,MATCH(Çeyreklik!$A4,Bilanço!$A:$A,0),0),HLOOKUP(B$1,Bilanço!$1:$151,MATCH(Çeyreklik!$A4,Bilanço!$A:$A,0),0)-HLOOKUP(A$1,Bilanço!$1:$151,MATCH(Çeyreklik!$A4,Bilanço!$A:$A,0),0)),IF(MID(B$2,6,7)="3",HLOOKUP(B$1,Bilanço!$1:$151,MATCH(Çeyreklik!$A4,Bilanço!$A:$A,0),0),HLOOKUP(B$1,Bilanço!$1:$151,MATCH(Çeyreklik!$A4,Bilanço!$A:$A,0),0)-HLOOKUP(Bilanço!$B$1,Bilanço!$1:$151,MATCH(Çeyreklik!$A4,Bilanço!$A:$A,0),0))),"") -> -1557506000 | C4: =IFERROR(IF(MID(C$2,6,7)="3",HLOOKUP(C$1,Bilanço!$1:$151,MATCH(Çeyreklik!$A4,Bilanço!$A:$A,0),0),HLOOKUP(C$1,Bilanço!$1:$151,MATCH(Çeyreklik!$A4,Bilanço!$A:$A,0),0)-HLOOKUP(B$1,Bilanço!$1:$151,MATCH(Çeyreklik!$A4,Bilanço!$A:$A,0),0)),"") -> -1646929000 | D4: =IFERROR(IF(MID(D$2,6,7)="3",HLOOKUP(D$1,Bilanço!$1:$151,MATCH(Çeyreklik!$A4,Bilanço!$A:$A,0),0),HLOOKUP(D$1,Bilanço!$1:$151,MATCH(Çeyreklik!$A4,Bilanço!$A:$A,0),0)-HLOOKUP(C$1,Bilanço!$1:$151,MATCH(Çeyreklik!$A4,Bilanço!$A:$A,0),0)),"") -> -1914092000 | E4: =IFERROR(IF(MID(E$2,6,7)="3",HLOOKUP(E$1,Bilanço!$1:$151,MATCH(Çeyreklik!$A4,Bilanço!$A:$A,0),0),HLOOKUP(E$1,Bilanço!$1:$151,MATCH(Çeyreklik!$A4,Bilanço!$A:$A,0),0)-HLOOKUP(D$1,Bilanço!$1:$151,MATCH(Çeyreklik!$A4,Bilanço!$A:$A,0),0)),"") -> -1921419000 | F4: =IFERROR(IF(MID(F$2,6,7)="3",HLOOKUP(F$1,Bilanço!$1:$151,MATCH(Çeyreklik!$A4,Bilanço!$A:$A,0),0),HLOOKUP(F$1,Bilanço!$1:$151,MATCH(Çeyreklik!$A4,Bilanço!$A:$A,0),0)-HLOOKUP(E$1,Bilanço!$1:$151,MATCH(Çeyreklik!$A4,Bilanço!$A:$A,0),0)),"") -> -1947709000 | G4: =IFERROR(IF(MID(G$2,6,7)="3",HLOOKUP(G$1,Bilanço!$1:$151,MATCH(Çeyreklik!$A4,Bilanço!$A:$A,0),0),HLOOKUP(G$1,Bilanço!$1:$151,MATCH(Çeyreklik!$A4,Bilanço!$A:$A,0),0)-HLOOKUP(F$1,Bilanço!$1:$151,MATCH(Çeyreklik!$A4,Bilanço!$A:$A,0),0)),"") -> -2171949000 | H4: =IFERROR(IF(MID(H$2,6,7)="3",HLOOKUP(H$1,Bilanço!$1:$151,MATCH(Çeyreklik!$A4,Bilanço!$A:$A,0),0),HLOOKUP(H$1,Bilanço!$1:$151,MATCH(Çeyreklik!$A4,Bilanço!$A:$A,0),0)-HLOOKUP(G$1,Bilanço!$1:$151,MATCH(Çeyreklik!$A4,Bilanço!$A:$A,0),0)),"") -> -2883588000 | I4: =IFERROR(IF(MID(I$2,6,7)="3",HLOOKUP(I$1,Bilanço!$1:$151,MATCH(Çeyreklik!$A4,Bilanço!$A:$A,0),0),HLOOKUP(I$1,Bilanço!$1:$151,MATCH(Çeyreklik!$A4,Bilanço!$A:$A,0),0)-HLOOKUP(H$1,Bilanço!$1:$151,MATCH(Çeyreklik!$A4,Bilanço!$A:$A,0),0)),"") -> -4036928000 | J4: =IFERROR(IF(MID(J$2,6,7)="3",HLOOKUP(J$1,Bilanço!$1:$151,MATCH(Çeyreklik!$A4,Bilanço!$A:$A,0),0),HLOOKUP(J$1,Bilanço!$1:$151,MATCH(Çeyreklik!$A4,Bilanço!$A:$A,0),0)-HLOOKUP(I$1,Bilanço!$1:$151,MATCH(Çeyreklik!$A4,Bilanço!$A:$A,0),0)),"") -> -4293332000 | ... W4: =IFERROR(IF(MID(W$2,6,7)="3",HLOOKUP(W$1,Bilanço!$1:$151,MATCH(Çeyreklik!$A4,Bilanço!$A:$A,0),0),HLOOKUP(W$1,Bilanço!$1:$151,MATCH(Çeyreklik!$A4,Bilanço!$A:$A,0),0)-HLOOKUP(V$1,Bilanço!$1:$151,MATCH(Çeyreklik!$A4,Bilanço!$A:$A,0),0)),"") -> -20667776000
A5: =Data!A76 -> Ticari Faaliyetlerden Diğer Kar (Zarar) | B5: =IFERROR(IF($B$2="2022/3",IF(MID(B$2,6,7)="3",HLOOKUP(B$1,Bilanço!$1:$151,MATCH(Çeyreklik!$A5,Bilanço!$A:$A,0),0),HLOOKUP(B$1,Bilanço!$1:$151,MATCH(Çeyreklik!$A5,Bilanço!$A:$A,0),0)-HLOOKUP(A$1,Bilanço!$1:$151,MATCH(Çeyreklik!$A5,Bilanço!$A:$A,0),0)),IF(MID(B$2,6,7)="3",HLOOKUP(B$1,Bilanço!$1:$151,MATCH(Çeyreklik!$A5,Bilanço!$A:$A,0),0),HLOOKUP(B$1,Bilanço!$1:$151,MATCH(Çeyreklik!$A5,Bilanço!$A:$A,0),0)-HLOOKUP(Bilanço!$B$1,Bilanço!$1:$151,MATCH(Çeyreklik!$A5,Bilanço!$A:$A,0),0))),"") -> 0 | C5: =IFERROR(IF(MID(C$2,6,7)="3",HLOOKUP(C$1,Bilanço!$1:$151,MATCH(Çeyreklik!$A5,Bilanço!$A:$A,0),0),HLOOKUP(C$1,Bilanço!$1:$151,MATCH(Çeyreklik!$A5,Bilanço!$A:$A,0),0)-HLOOKUP(B$1,Bilanço!$1:$151,MATCH(Çeyreklik!$A5,Bilanço!$A:$A,0),0)),"") -> 0 | D5: =IFERROR(IF(MID(D$2,6,7)="3",HLOOKUP(D$1,Bilanço!$1:$151,MATCH(Çeyreklik!$A5,Bilanço!$A:$A,0),0),HLOOKUP(D$1,Bilanço!$1:$151,MATCH(Çeyreklik!$A5,Bilanço!$A:$A,0),0)-HLOOKUP(C$1,Bilanço!$1:$151,MATCH(Çeyreklik!$A5,Bilanço!$A:$A,0),0)),"") -> 0 | E5: =IFERROR(IF(MID(E$2,6,7)="3",HLOOKUP(E$1,Bilanço!$1:$151,MATCH(Çeyreklik!$A5,Bilanço!$A:$A,0),0),HLOOKUP(E$1,Bilanço!$1:$151,MATCH(Çeyreklik!$A5,Bilanço!$A:$A,0),0)-HLOOKUP(D$1,Bilanço!$1:$151,MATCH(Çeyreklik!$A5,Bilanço!$A:$A,0),0)),"") -> 0 | F5: =IFERROR(IF(MID(F$2,6,7)="3",HLOOKUP(F$1,Bilanço!$1:$151,MATCH(Çeyreklik!$A5,Bilanço!$A:$A,0),0),HLOOKUP(F$1,Bilanço!$1:$151,MATCH(Çeyreklik!$A5,Bilanço!$A:$A,0),0)-HLOOKUP(E$1,Bilanço!$1:$151,MATCH(Çeyreklik!$A5,Bilanço!$A:$A,0),0)),"") -> 0 | G5: =IFERROR(IF(MID(G$2,6,7)="3",HLOOKUP(G$1,Bilanço!$1:$151,MATCH(Çeyreklik!$A5,Bilanço!$A:$A,0),0),HLOOKUP(G$1,Bilanço!$1:$151,MATCH(Çeyreklik!$A5,Bilanço!$A:$A,0),0)-HLOOKUP(F$1,Bilanço!$1:$151,MATCH(Çeyreklik!$A5,Bilanço!$A:$A,0),0)),"") -> 0 | H5: =IFERROR(IF(MID(H$2,6,7)="3",HLOOKUP(H$1,Bilanço!$1:$151,MATCH(Çeyreklik!$A5,Bilanço!$A:$A,0),0),HLOOKUP(H$1,Bilanço!$1:$151,MATCH(Çeyreklik!$A5,Bilanço!$A:$A,0),0)-HLOOKUP(G$1,Bilanço!$1:$151,MATCH(Çeyreklik!$A5,Bilanço!$A:$A,0),0)),"") -> 0 | I5: =IFERROR(IF(MID(I$2,6,7)="3",HLOOKUP(I$1,Bilanço!$1:$151,MATCH(Çeyreklik!$A5,Bilanço!$A:$A,0),0),HLOOKUP(I$1,Bilanço!$1:$151,MATCH(Çeyreklik!$A5,Bilanço!$A:$A,0),0)-HLOOKUP(H$1,Bilanço!$1:$151,MATCH(Çeyreklik!$A5,Bilanço!$A:$A,0),0)),"") -> 0 | J5: =IFERROR(IF(MID(J$2,6,7)="3",HLOOKUP(J$1,Bilanço!$1:$151,MATCH(Çeyreklik!$A5,Bilanço!$A:$A,0),0),HLOOKUP(J$1,Bilanço!$1:$151,MATCH(Çeyreklik!$A5,Bilanço!$A:$A,0),0)-HLOOKUP(I$1,Bilanço!$1:$151,MATCH(Çeyreklik!$A5,Bilanço!$A:$A,0),0)),"") -> 0 | ... W5: =IFERROR(IF(MID(W$2,6,7)="3",HLOOKUP(W$1,Bilanço!$1:$151,MATCH(Çeyreklik!$A5,Bilanço!$A:$A,0),0),HLOOKUP(W$1,Bilanço!$1:$151,MATCH(Çeyreklik!$A5,Bilanço!$A:$A,0),0)-HLOOKUP(V$1,Bilanço!$1:$151,MATCH(Çeyreklik!$A5,Bilanço!$A:$A,0),0)),"") -> 0
A6: =Data!A77 -> Ticari Faaliyetlerden Brüt Kar (Zarar) | B6: =IFERROR(IF($B$2="2022/3",IF(MID(B$2,6,7)="3",HLOOKUP(B$1,Bilanço!$1:$151,MATCH(Çeyreklik!$A6,Bilanço!$A:$A,0),0),HLOOKUP(B$1,Bilanço!$1:$151,MATCH(Çeyreklik!$A6,Bilanço!$A:$A,0),0)-HLOOKUP(A$1,Bilanço!$1:$151,MATCH(Çeyreklik!$A6,Bilanço!$A:$A,0),0)),IF(MID(B$2,6,7)="3",HLOOKUP(B$1,Bilanço!$1:$151,MATCH(Çeyreklik!$A6,Bilanço!$A:$A,0),0),HLOOKUP(B$1,Bilanço!$1:$151,MATCH(Çeyreklik!$A6,Bilanço!$A:$A,0),0)-HLOOKUP(Bilanço!$B$1,Bilanço!$1:$151,MATCH(Çeyreklik!$A6,Bilanço!$A:$A,0),0))),"") -> 587135000 | C6: =IFERROR(IF(MID(C$2,6,7)="3",HLOOKUP(C$1,Bilanço!$1:$151,MATCH(Çeyreklik!$A6,Bilanço!$A:$A,0),0),HLOOKUP(C$1,Bilanço!$1:$151,MATCH(Çeyreklik!$A6,Bilanço!$A:$A,0),0)-HLOOKUP(B$1,Bilanço!$1:$151,MATCH(Çeyreklik!$A6,Bilanço!$A:$A,0),0)),"") -> 808916000 | D6: =IFERROR(IF(MID(D$2,6,7)="3",HLOOKUP(D$1,Bilanço!$1:$151,MATCH(Çeyreklik!$A6,Bilanço!$A:$A,0),0),HLOOKUP(D$1,Bilanço!$1:$151,MATCH(Çeyreklik!$A6,Bilanço!$A:$A,0),0)-HLOOKUP(C$1,Bilanço!$1:$151,MATCH(Çeyreklik!$A6,Bilanço!$A:$A,0),0)),"") -> 824926000 | E6: =IFERROR(IF(MID(E$2,6,7)="3",HLOOKUP(E$1,Bilanço!$1:$151,MATCH(Çeyreklik!$A6,Bilanço!$A:$A,0),0),HLOOKUP(E$1,Bilanço!$1:$151,MATCH(Çeyreklik!$A6,Bilanço!$A:$A,0),0)-HLOOKUP(D$1,Bilanço!$1:$151,MATCH(Çeyreklik!$A6,Bilanço!$A:$A,0),0)),"") -> 862338000 | F6: =IFERROR(IF(MID(F$2,6,7)="3",HLOOKUP(F$1,Bilanço!$1:$151,MATCH(Çeyreklik!$A6,Bilanço!$A:$A,0),0),HLOOKUP(F$1,Bilanço!$1:$151,MATCH(Çeyreklik!$A6,Bilanço!$A:$A,0),0)-HLOOKUP(E$1,Bilanço!$1:$151,MATCH(Çeyreklik!$A6,Bilanço!$A:$A,0),0)),"") -> 711358000 | G6: =IFERROR(IF(MID(G$2,6,7)="3",HLOOKUP(G$1,Bilanço!$1:$151,MATCH(Çeyreklik!$A6,Bilanço!$A:$A,0),0),HLOOKUP(G$1,Bilanço!$1:$151,MATCH(Çeyreklik!$A6,Bilanço!$A:$A,0),0)-HLOOKUP(F$1,Bilanço!$1:$151,MATCH(Çeyreklik!$A6,Bilanço!$A:$A,0),0)),"") -> 804184000 | H6: =IFERROR(IF(MID(H$2,6,7)="3",HLOOKUP(H$1,Bilanço!$1:$151,MATCH(Çeyreklik!$A6,Bilanço!$A:$A,0),0),HLOOKUP(H$1,Bilanço!$1:$151,MATCH(Çeyreklik!$A6,Bilanço!$A:$A,0),0)-HLOOKUP(G$1,Bilanço!$1:$151,MATCH(Çeyreklik!$A6,Bilanço!$A:$A,0),0)),"") -> 1234535000 | I6: =IFERROR(IF(MID(I$2,6,7)="3",HLOOKUP(I$1,Bilanço!$1:$151,MATCH(Çeyreklik!$A6,Bilanço!$A:$A,0),0),HLOOKUP(I$1,Bilanço!$1:$151,MATCH(Çeyreklik!$A6,Bilanço!$A:$A,0),0)-HLOOKUP(H$1,Bilanço!$1:$151,MATCH(Çeyreklik!$A6,Bilanço!$A:$A,0),0)),"") -> 1849090000 | J6: =IFERROR(IF(MID(J$2,6,7)="3",HLOOKUP(J$1,Bilanço!$1:$151,MATCH(Çeyreklik!$A6,Bilanço!$A:$A,0),0),HLOOKUP(J$1,Bilanço!$1:$151,MATCH(Çeyreklik!$A6,Bilanço!$A:$A,0),0)-HLOOKUP(I$1,Bilanço!$1:$151,MATCH(Çeyreklik!$A6,Bilanço!$A:$A,0),0)),"") -> 1697710000 | ... W6: =IFERROR(IF(MID(W$2,6,7)="3",HLOOKUP(W$1,Bilanço!$1:$151,MATCH(Çeyreklik!$A6,Bilanço!$A:$A,0),0),HLOOKUP(W$1,Bilanço!$1:$151,MATCH(Çeyreklik!$A6,Bilanço!$A:$A,0),0)-HLOOKUP(V$1,Bilanço!$1:$151,MATCH(Çeyreklik!$A6,Bilanço!$A:$A,0),0)),"") -> 8618586000
A7: =Data!A78 -> Faiz, Ücret, Prim, Komisyon ve Diğer Gelirler | B7: =IFERROR(IF($B$2="2022/3",IF(MID(B$2,6,7)="3",HLOOKUP(B$1,Bilanço!$1:$151,MATCH(Çeyreklik!$A7,Bilanço!$A:$A,0),0),HLOOKUP(B$1,Bilanço!$1:$151,MATCH(Çeyreklik!$A7,Bilanço!$A:$A,0),0)-HLOOKUP(A$1,Bilanço!$1:$151,MATCH(Çeyreklik!$A7,Bilanço!$A:$A,0),0)),IF(MID(B$2,6,7)="3",HLOOKUP(B$1,Bilanço!$1:$151,MATCH(Çeyreklik!$A7,Bilanço!$A:$A,0),0),HLOOKUP(B$1,Bilanço!$1:$151,MATCH(Çeyreklik!$A7,Bilanço!$A:$A,0),0)-HLOOKUP(Bilanço!$B$1,Bilanço!$1:$151,MATCH(Çeyreklik!$A7,Bilanço!$A:$A,0),0))),"") -> 0 | C7: =IFERROR(IF(MID(C$2,6,7)="3",HLOOKUP(C$1,Bilanço!$1:$151,MATCH(Çeyreklik!$A7,Bilanço!$A:$A,0),0),HLOOKUP(C$1,Bilanço!$1:$151,MATCH(Çeyreklik!$A7,Bilanço!$A:$A,0),0)-HLOOKUP(B$1,Bilanço!$1:$151,MATCH(Çeyreklik!$A7,Bilanço!$A:$A,0),0)),"") -> 0 | D7: =IFERROR(IF(MID(D$2,6,7)="3",HLOOKUP(D$1,Bilanço!$1:$151,MATCH(Çeyreklik!$A7,Bilanço!$A:$A,0),0),HLOOKUP(D$1,Bilanço!$1:$151,MATCH(Çeyreklik!$A7,Bilanço!$A:$A,0),0)-HLOOKUP(C$1,Bilanço!$1:$151,MATCH(Çeyreklik!$A7,Bilanço!$A:$A,0),0)),"") -> 0 | E7: =IFERROR(IF(MID(E$2,6,7)="3",HLOOKUP(E$1,Bilanço!$1:$151,MATCH(Çeyreklik!$A7,Bilanço!$A:$A,0),0),HLOOKUP(E$1,Bilanço!$1:$151,MATCH(Çeyreklik!$A7,Bilanço!$A:$A,0),0)-HLOOKUP(D$1,Bilanço!$1:$151,MATCH(Çeyreklik!$A7,Bilanço!$A:$A,0),0)),"") -> 0 | F7: =IFERROR(IF(MID(F$2,6,7)="3",HLOOKUP(F$1,Bilanço!$1:$151,MATCH(Çeyreklik!$A7,Bilanço!$A:$A,0),0),HLOOKUP(F$1,Bilanço!$1:$151,MATCH(Çeyreklik!$A7,Bilanço!$A:$A,0),0)-HLOOKUP(E$1,Bilanço!$1:$151,MATCH(Çeyreklik!$A7,Bilanço!$A:$A,0),0)),"") -> 0 | G7: =IFERROR(IF(MID(G$2,6,7)="3",HLOOKUP(G$1,Bilanço!$1:$151,MATCH(Çeyreklik!$A7,Bilanço!$A:$A,0),0),HLOOKUP(G$1,Bilanço!$1:$151,MATCH(Çeyreklik!$A7,Bilanço!$A:$A,0),0)-HLOOKUP(F$1,Bilanço!$1:$151,MATCH(Çeyreklik!$A7,Bilanço!$A:$A,0),0)),"") -> 0 | H7: =IFERROR(IF(MID(H$2,6,7)="3",HLOOKUP(H$1,Bilanço!$1:$151,MATCH(Çeyreklik!$A7,Bilanço!$A:$A,0),0),HLOOKUP(H$1,Bilanço!$1:$151,MATCH(Çeyreklik!$A7,Bilanço!$A:$A,0),0)-HLOOKUP(G$1,Bilanço!$1:$151,MATCH(Çeyreklik!$A7,Bilanço!$A:$A,0),0)),"") -> 0 | I7: =IFERROR(IF(MID(I$2,6,7)="3",HLOOKUP(I$1,Bilanço!$1:$151,MATCH(Çeyreklik!$A7,Bilanço!$A:$A,0),0),HLOOKUP(I$1,Bilanço!$1:$151,MATCH(Çeyreklik!$A7,Bilanço!$A:$A,0),0)-HLOOKUP(H$1,Bilanço!$1:$151,MATCH(Çeyreklik!$A7,Bilanço!$A:$A,0),0)),"") -> 0 | J7: =IFERROR(IF(MID(J$2,6,7)="3",HLOOKUP(J$1,Bilanço!$1:$151,MATCH(Çeyreklik!$A7,Bilanço!$A:$A,0),0),HLOOKUP(J$1,Bilanço!$1:$151,MATCH(Çeyreklik!$A7,Bilanço!$A:$A,0),0)-HLOOKUP(I$1,Bilanço!$1:$151,MATCH(Çeyreklik!$A7,Bilanço!$A:$A,0),0)),"") -> 0 | ... W7: =IFERROR(IF(MID(W$2,6,7)="3",HLOOKUP(W$1,Bilanço!$1:$151,MATCH(Çeyreklik!$A7,Bilanço!$A:$A,0),0),HLOOKUP(W$1,Bilanço!$1:$151,MATCH(Çeyreklik!$A7,Bilanço!$A:$A,0),0)-HLOOKUP(V$1,Bilanço!$1:$151,MATCH(Çeyreklik!$A7,Bilanço!$A:$A,0),0)),"") -> 0
A8: =Data!A79 -> Faiz, Ücret, Prim, Komisyon ve Diğer Giderler (-) | B8: =IFERROR(IF($B$2="2022/3",IF(MID(B$2,6,7)="3",HLOOKUP(B$1,Bilanço!$1:$151,MATCH(Çeyreklik!$A8,Bilanço!$A:$A,0),0),HLOOKUP(B$1,Bilanço!$1:$151,MATCH(Çeyreklik!$A8,Bilanço!$A:$A,0),0)-HLOOKUP(A$1,Bilanço!$1:$151,MATCH(Çeyreklik!$A8,Bilanço!$A:$A,0),0)),IF(MID(B$2,6,7)="3",HLOOKUP(B$1,Bilanço!$1:$151,MATCH(Çeyreklik!$A8,Bilanço!$A:$A,0),0),HLOOKUP(B$1,Bilanço!$1:$151,MATCH(Çeyreklik!$A8,Bilanço!$A:$A,0),0)-HLOOKUP(Bilanço!$B$1,Bilanço!$1:$151,MATCH(Çeyreklik!$A8,Bilanço!$A:$A,0),0))),"") -> 0 | C8: =IFERROR(IF(MID(C$2,6,7)="3",HLOOKUP(C$1,Bilanço!$1:$151,MATCH(Çeyreklik!$A8,Bilanço!$A:$A,0),0),HLOOKUP(C$1,Bilanço!$1:$151,MATCH(Çeyreklik!$A8,Bilanço!$A:$A,0),0)-HLOOKUP(B$1,Bilanço!$1:$151,MATCH(Çeyreklik!$A8,Bilanço!$A:$A,0),0)),"") -> 0 | D8: =IFERROR(IF(MID(D$2,6,7)="3",HLOOKUP(D$1,Bilanço!$1:$151,MATCH(Çeyreklik!$A8,Bilanço!$A:$A,0),0),HLOOKUP(D$1,Bilanço!$1:$151,MATCH(Çeyreklik!$A8,Bilanço!$A:$A,0),0)-HLOOKUP(C$1,Bilanço!$1:$151,MATCH(Çeyreklik!$A8,Bilanço!$A:$A,0),0)),"") -> 0 | E8: =IFERROR(IF(MID(E$2,6,7)="3",HLOOKUP(E$1,Bilanço!$1:$151,MATCH(Çeyreklik!$A8,Bilanço!$A:$A,0),0),HLOOKUP(E$1,Bilanço!$1:$151,MATCH(Çeyreklik!$A8,Bilanço!$A:$A,0),0)-HLOOKUP(D$1,Bilanço!$1:$151,MATCH(Çeyreklik!$A8,Bilanço!$A:$A,0),0)),"") -> 0 | F8: =IFERROR(IF(MID(F$2,6,7)="3",HLOOKUP(F$1,Bilanço!$1:$151,MATCH(Çeyreklik!$A8,Bilanço!$A:$A,0),0),HLOOKUP(F$1,Bilanço!$1:$151,MATCH(Çeyreklik!$A8,Bilanço!$A:$A,0),0)-HLOOKUP(E$1,Bilanço!$1:$151,MATCH(Çeyreklik!$A8,Bilanço!$A:$A,0),0)),"") -> 0 | G8: =IFERROR(IF(MID(G$2,6,7)="3",HLOOKUP(G$1,Bilanço!$1:$151,MATCH(Çeyreklik!$A8,Bilanço!$A:$A,0),0),HLOOKUP(G$1,Bilanço!$1:$151,MATCH(Çeyreklik!$A8,Bilanço!$A:$A,0),0)-HLOOKUP(F$1,Bilanço!$1:$151,MATCH(Çeyreklik!$A8,Bilanço!$A:$A,0),0)),"") -> 0 | H8: =IFERROR(IF(MID(H$2,6,7)="3",HLOOKUP(H$1,Bilanço!$1:$151,MATCH(Çeyreklik!$A8,Bilanço!$A:$A,0),0),HLOOKUP(H$1,Bilanço!$1:$151,MATCH(Çeyreklik!$A8,Bilanço!$A:$A,0),0)-HLOOKUP(G$1,Bilanço!$1:$151,MATCH(Çeyreklik!$A8,Bilanço!$A:$A,0),0)),"") -> 0 | I8: =IFERROR(IF(MID(I$2,6,7)="3",HLOOKUP(I$1,Bilanço!$1:$151,MATCH(Çeyreklik!$A8,Bilanço!$A:$A,0),0),HLOOKUP(I$1,Bilanço!$1:$151,MATCH(Çeyreklik!$A8,Bilanço!$A:$A,0),0)-HLOOKUP(H$1,Bilanço!$1:$151,MATCH(Çeyreklik!$A8,Bilanço!$A:$A,0),0)),"") -> 0 | J8: =IFERROR(IF(MID(J$2,6,7)="3",HLOOKUP(J$1,Bilanço!$1:$151,MATCH(Çeyreklik!$A8,Bilanço!$A:$A,0),0),HLOOKUP(J$1,Bilanço!$1:$151,MATCH(Çeyreklik!$A8,Bilanço!$A:$A,0),0)-HLOOKUP(I$1,Bilanço!$1:$151,MATCH(Çeyreklik!$A8,Bilanço!$A:$A,0),0)),"") -> 0 | ... W8: =IFERROR(IF(MID(W$2,6,7)="3",HLOOKUP(W$1,Bilanço!$1:$151,MATCH(Çeyreklik!$A8,Bilanço!$A:$A,0),0),HLOOKUP(W$1,Bilanço!$1:$151,MATCH(Çeyreklik!$A8,Bilanço!$A:$A,0),0)-HLOOKUP(V$1,Bilanço!$1:$151,MATCH(Çeyreklik!$A8,Bilanço!$A:$A,0),0)),"") -> 0
A9: =Data!A80 -> Finans Sektörü Faaliyetlerinden Diğer Kar (Zarar) | B9: =IFERROR(IF($B$2="2022/3",IF(MID(B$2,6,7)="3",HLOOKUP(B$1,Bilanço!$1:$151,MATCH(Çeyreklik!$A9,Bilanço!$A:$A,0),0),HLOOKUP(B$1,Bilanço!$1:$151,MATCH(Çeyreklik!$A9,Bilanço!$A:$A,0),0)-HLOOKUP(A$1,Bilanço!$1:$151,MATCH(Çeyreklik!$A9,Bilanço!$A:$A,0),0)),IF(MID(B$2,6,7)="3",HLOOKUP(B$1,Bilanço!$1:$151,MATCH(Çeyreklik!$A9,Bilanço!$A:$A,0),0),HLOOKUP(B$1,Bilanço!$1:$151,MATCH(Çeyreklik!$A9,Bilanço!$A:$A,0),0)-HLOOKUP(Bilanço!$B$1,Bilanço!$1:$151,MATCH(Çeyreklik!$A9,Bilanço!$A:$A,0),0))),"") -> 0 | C9: =IFERROR(IF(MID(C$2,6,7)="3",HLOOKUP(C$1,Bilanço!$1:$151,MATCH(Çeyreklik!$A9,Bilanço!$A:$A,0),0),HLOOKUP(C$1,Bilanço!$1:$151,MATCH(Çeyreklik!$A9,Bilanço!$A:$A,0),0)-HLOOKUP(B$1,Bilanço!$1:$151,MATCH(Çeyreklik!$A9,Bilanço!$A:$A,0),0)),"") -> 0 | D9: =IFERROR(IF(MID(D$2,6,7)="3",HLOOKUP(D$1,Bilanço!$1:$151,MATCH(Çeyreklik!$A9,Bilanço!$A:$A,0),0),HLOOKUP(D$1,Bilanço!$1:$151,MATCH(Çeyreklik!$A9,Bilanço!$A:$A,0),0)-HLOOKUP(C$1,Bilanço!$1:$151,MATCH(Çeyreklik!$A9,Bilanço!$A:$A,0),0)),"") -> 0 | E9: =IFERROR(IF(MID(E$2,6,7)="3",HLOOKUP(E$1,Bilanço!$1:$151,MATCH(Çeyreklik!$A9,Bilanço!$A:$A,0),0),HLOOKUP(E$1,Bilanço!$1:$151,MATCH(Çeyreklik!$A9,Bilanço!$A:$A,0),0)-HLOOKUP(D$1,Bilanço!$1:$151,MATCH(Çeyreklik!$A9,Bilanço!$A:$A,0),0)),"") -> 0 | F9: =IFERROR(IF(MID(F$2,6,7)="3",HLOOKUP(F$1,Bilanço!$1:$151,MATCH(Çeyreklik!$A9,Bilanço!$A:$A,0),0),HLOOKUP(F$1,Bilanço!$1:$151,MATCH(Çeyreklik!$A9,Bilanço!$A:$A,0),0)-HLOOKUP(E$1,Bilanço!$1:$151,MATCH(Çeyreklik!$A9,Bilanço!$A:$A,0),0)),"") -> 0 | G9: =IFERROR(IF(MID(G$2,6,7)="3",HLOOKUP(G$1,Bilanço!$1:$151,MATCH(Çeyreklik!$A9,Bilanço!$A:$A,0),0),HLOOKUP(G$1,Bilanço!$1:$151,MATCH(Çeyreklik!$A9,Bilanço!$A:$A,0),0)-HLOOKUP(F$1,Bilanço!$1:$151,MATCH(Çeyreklik!$A9,Bilanço!$A:$A,0),0)),"") -> 0 | H9: =IFERROR(IF(MID(H$2,6,7)="3",HLOOKUP(H$1,Bilanço!$1:$151,MATCH(Çeyreklik!$A9,Bilanço!$A:$A,0),0),HLOOKUP(H$1,Bilanço!$1:$151,MATCH(Çeyreklik!$A9,Bilanço!$A:$A,0),0)-HLOOKUP(G$1,Bilanço!$1:$151,MATCH(Çeyreklik!$A9,Bilanço!$A:$A,0),0)),"") -> 0 | I9: =IFERROR(IF(MID(I$2,6,7)="3",HLOOKUP(I$1,Bilanço!$1:$151,MATCH(Çeyreklik!$A9,Bilanço!$A:$A,0),0),HLOOKUP(I$1,Bilanço!$1:$151,MATCH(Çeyreklik!$A9,Bilanço!$A:$A,0),0)-HLOOKUP(H$1,Bilanço!$1:$151,MATCH(Çeyreklik!$A9,Bilanço!$A:$A,0),0)),"") -> 0 | J9: =IFERROR(IF(MID(J$2,6,7)="3",HLOOKUP(J$1,Bilanço!$1:$151,MATCH(Çeyreklik!$A9,Bilanço!$A:$A,0),0),HLOOKUP(J$1,Bilanço!$1:$151,MATCH(Çeyreklik!$A9,Bilanço!$A:$A,0),0)-HLOOKUP(I$1,Bilanço!$1:$151,MATCH(Çeyreklik!$A9,Bilanço!$A:$A,0),0)),"") -> 0 | ... W9: =IFERROR(IF(MID(W$2,6,7)="3",HLOOKUP(W$1,Bilanço!$1:$151,MATCH(Çeyreklik!$A9,Bilanço!$A:$A,0),0),HLOOKUP(W$1,Bilanço!$1:$151,MATCH(Çeyreklik!$A9,Bilanço!$A:$A,0),0)-HLOOKUP(V$1,Bilanço!$1:$151,MATCH(Çeyreklik!$A9,Bilanço!$A:$A,0),0)),"") -> 0
A10: =Data!A81 -> Finans Sektörü Faaliyetlerinden Brüt Kar (Zarar) | B10: =IFERROR(IF($B$2="2022/3",IF(MID(B$2,6,7)="3",HLOOKUP(B$1,Bilanço!$1:$151,MATCH(Çeyreklik!$A10,Bilanço!$A:$A,0),0),HLOOKUP(B$1,Bilanço!$1:$151,MATCH(Çeyreklik!$A10,Bilanço!$A:$A,0),0)-HLOOKUP(A$1,Bilanço!$1:$151,MATCH(Çeyreklik!$A10,Bilanço!$A:$A,0),0)),IF(MID(B$2,6,7)="3",HLOOKUP(B$1,Bilanço!$1:$151,MATCH(Çeyreklik!$A10,Bilanço!$A:$A,0),0),HLOOKUP(B$1,Bilanço!$1:$151,MATCH(Çeyreklik!$A10,Bilanço!$A:$A,0),0)-HLOOKUP(Bilanço!$B$1,Bilanço!$1:$151,MATCH(Çeyreklik!$A10,Bilanço!$A:$A,0),0))),"") -> 0 | C10: =IFERROR(IF(MID(C$2,6,7)="3",HLOOKUP(C$1,Bilanço!$1:$151,MATCH(Çeyreklik!$A10,Bilanço!$A:$A,0),0),HLOOKUP(C$1,Bilanço!$1:$151,MATCH(Çeyreklik!$A10,Bilanço!$A:$A,0),0)-HLOOKUP(B$1,Bilanço!$1:$151,MATCH(Çeyreklik!$A10,Bilanço!$A:$A,0),0)),"") -> 0 | D10: =IFERROR(IF(MID(D$2,6,7)="3",HLOOKUP(D$1,Bilanço!$1:$151,MATCH(Çeyreklik!$A10,Bilanço!$A:$A,0),0),HLOOKUP(D$1,Bilanço!$1:$151,MATCH(Çeyreklik!$A10,Bilanço!$A:$A,0),0)-HLOOKUP(C$1,Bilanço!$1:$151,MATCH(Çeyreklik!$A10,Bilanço!$A:$A,0),0)),"") -> 0 | E10: =IFERROR(IF(MID(E$2,6,7)="3",HLOOKUP(E$1,Bilanço!$1:$151,MATCH(Çeyreklik!$A10,Bilanço!$A:$A,0),0),HLOOKUP(E$1,Bilanço!$1:$151,MATCH(Çeyreklik!$A10,Bilanço!$A:$A,0),0)-HLOOKUP(D$1,Bilanço!$1:$151,MATCH(Çeyreklik!$A10,Bilanço!$A:$A,0),0)),"") -> 0 | F10: =IFERROR(IF(MID(F$2,6,7)="3",HLOOKUP(F$1,Bilanço!$1:$151,MATCH(Çeyreklik!$A10,Bilanço!$A:$A,0),0),HLOOKUP(F$1,Bilanço!$1:$151,MATCH(Çeyreklik!$A10,Bilanço!$A:$A,0),0)-HLOOKUP(E$1,Bilanço!$1:$151,MATCH(Çeyreklik!$A10,Bilanço!$A:$A,0),0)),"") -> 0 | G10: =IFERROR(IF(MID(G$2,6,7)="3",HLOOKUP(G$1,Bilanço!$1:$151,MATCH(Çeyreklik!$A10,Bilanço!$A:$A,0),0),HLOOKUP(G$1,Bilanço!$1:$151,MATCH(Çeyreklik!$A10,Bilanço!$A:$A,0),0)-HLOOKUP(F$1,Bilanço!$1:$151,MATCH(Çeyreklik!$A10,Bilanço!$A:$A,0),0)),"") -> 0 | H10: =IFERROR(IF(MID(H$2,6,7)="3",HLOOKUP(H$1,Bilanço!$1:$151,MATCH(Çeyreklik!$A10,Bilanço!$A:$A,0),0),HLOOKUP(H$1,Bilanço!$1:$151,MATCH(Çeyreklik!$A10,Bilanço!$A:$A,0),0)-HLOOKUP(G$1,Bilanço!$1:$151,MATCH(Çeyreklik!$A10,Bilanço!$A:$A,0),0)),"") -> 0 | I10: =IFERROR(IF(MID(I$2,6,7)="3",HLOOKUP(I$1,Bilanço!$1:$151,MATCH(Çeyreklik!$A10,Bilanço!$A:$A,0),0),HLOOKUP(I$1,Bilanço!$1:$151,MATCH(Çeyreklik!$A10,Bilanço!$A:$A,0),0)-HLOOKUP(H$1,Bilanço!$1:$151,MATCH(Çeyreklik!$A10,Bilanço!$A:$A,0),0)),"") -> 0 | J10: =IFERROR(IF(MID(J$2,6,7)="3",HLOOKUP(J$1,Bilanço!$1:$151,MATCH(Çeyreklik!$A10,Bilanço!$A:$A,0),0),HLOOKUP(J$1,Bilanço!$1:$151,MATCH(Çeyreklik!$A10,Bilanço!$A:$A,0),0)-HLOOKUP(I$1,Bilanço!$1:$151,MATCH(Çeyreklik!$A10,Bilanço!$A:$A,0),0)),"") -> 0 | ... W10: =IFERROR(IF(MID(W$2,6,7)="3",HLOOKUP(W$1,Bilanço!$1:$151,MATCH(Çeyreklik!$A10,Bilanço!$A:$A,0),0),HLOOKUP(W$1,Bilanço!$1:$151,MATCH(Çeyreklik!$A10,Bilanço!$A:$A,0),0)-HLOOKUP(V$1,Bilanço!$1:$151,MATCH(Çeyreklik!$A10,Bilanço!$A:$A,0),0)),"") -> 0
A11: =Data!A82 -> Diğer Gelir ve Giderler | B11: =IFERROR(IF($B$2="2022/3",IF(MID(B$2,6,7)="3",HLOOKUP(B$1,Bilanço!$1:$151,MATCH(Çeyreklik!$A11,Bilanço!$A:$A,0),0),HLOOKUP(B$1,Bilanço!$1:$151,MATCH(Çeyreklik!$A11,Bilanço!$A:$A,0),0)-HLOOKUP(A$1,Bilanço!$1:$151,MATCH(Çeyreklik!$A11,Bilanço!$A:$A,0),0)),IF(MID(B$2,6,7)="3",HLOOKUP(B$1,Bilanço!$1:$151,MATCH(Çeyreklik!$A11,Bilanço!$A:$A,0),0),HLOOKUP(B$1,Bilanço!$1:$151,MATCH(Çeyreklik!$A11,Bilanço!$A:$A,0),0)-HLOOKUP(Bilanço!$B$1,Bilanço!$1:$151,MATCH(Çeyreklik!$A11,Bilanço!$A:$A,0),0))),"") -> 0 | C11: =IFERROR(IF(MID(C$2,6,7)="3",HLOOKUP(C$1,Bilanço!$1:$151,MATCH(Çeyreklik!$A11,Bilanço!$A:$A,0),0),HLOOKUP(C$1,Bilanço!$1:$151,MATCH(Çeyreklik!$A11,Bilanço!$A:$A,0),0)-HLOOKUP(B$1,Bilanço!$1:$151,MATCH(Çeyreklik!$A11,Bilanço!$A:$A,0),0)),"") -> 0 | D11: =IFERROR(IF(MID(D$2,6,7)="3",HLOOKUP(D$1,Bilanço!$1:$151,MATCH(Çeyreklik!$A11,Bilanço!$A:$A,0),0),HLOOKUP(D$1,Bilanço!$1:$151,MATCH(Çeyreklik!$A11,Bilanço!$A:$A,0),0)-HLOOKUP(C$1,Bilanço!$1:$151,MATCH(Çeyreklik!$A11,Bilanço!$A:$A,0),0)),"") -> 0 | E11: =IFERROR(IF(MID(E$2,6,7)="3",HLOOKUP(E$1,Bilanço!$1:$151,MATCH(Çeyreklik!$A11,Bilanço!$A:$A,0),0),HLOOKUP(E$1,Bilanço!$1:$151,MATCH(Çeyreklik!$A11,Bilanço!$A:$A,0),0)-HLOOKUP(D$1,Bilanço!$1:$151,MATCH(Çeyreklik!$A11,Bilanço!$A:$A,0),0)),"") -> 0 | F11: =IFERROR(IF(MID(F$2,6,7)="3",HLOOKUP(F$1,Bilanço!$1:$151,MATCH(Çeyreklik!$A11,Bilanço!$A:$A,0),0),HLOOKUP(F$1,Bilanço!$1:$151,MATCH(Çeyreklik!$A11,Bilanço!$A:$A,0),0)-HLOOKUP(E$1,Bilanço!$1:$151,MATCH(Çeyreklik!$A11,Bilanço!$A:$A,0),0)),"") -> 0 | G11: =IFERROR(IF(MID(G$2,6,7)="3",HLOOKUP(G$1,Bilanço!$1:$151,MATCH(Çeyreklik!$A11,Bilanço!$A:$A,0),0),HLOOKUP(G$1,Bilanço!$1:$151,MATCH(Çeyreklik!$A11,Bilanço!$A:$A,0),0)-HLOOKUP(F$1,Bilanço!$1:$151,MATCH(Çeyreklik!$A11,Bilanço!$A:$A,0),0)),"") -> 0 | H11: =IFERROR(IF(MID(H$2,6,7)="3",HLOOKUP(H$1,Bilanço!$1:$151,MATCH(Çeyreklik!$A11,Bilanço!$A:$A,0),0),HLOOKUP(H$1,Bilanço!$1:$151,MATCH(Çeyreklik!$A11,Bilanço!$A:$A,0),0)-HLOOKUP(G$1,Bilanço!$1:$151,MATCH(Çeyreklik!$A11,Bilanço!$A:$A,0),0)),"") -> 0 | I11: =IFERROR(IF(MID(I$2,6,7)="3",HLOOKUP(I$1,Bilanço!$1:$151,MATCH(Çeyreklik!$A11,Bilanço!$A:$A,0),0),HLOOKUP(I$1,Bilanço!$1:$151,MATCH(Çeyreklik!$A11,Bilanço!$A:$A,0),0)-HLOOKUP(H$1,Bilanço!$1:$151,MATCH(Çeyreklik!$A11,Bilanço!$A:$A,0),0)),"") -> 0 | J11: =IFERROR(IF(MID(J$2,6,7)="3",HLOOKUP(J$1,Bilanço!$1:$151,MATCH(Çeyreklik!$A11,Bilanço!$A:$A,0),0),HLOOKUP(J$1,Bilanço!$1:$151,MATCH(Çeyreklik!$A11,Bilanço!$A:$A,0),0)-HLOOKUP(I$1,Bilanço!$1:$151,MATCH(Çeyreklik!$A11,Bilanço!$A:$A,0),0)),"") -> 0 | ... W11: =IFERROR(IF(MID(W$2,6,7)="3",HLOOKUP(W$1,Bilanço!$1:$151,MATCH(Çeyreklik!$A11,Bilanço!$A:$A,0),0),HLOOKUP(W$1,Bilanço!$1:$151,MATCH(Çeyreklik!$A11,Bilanço!$A:$A,0),0)-HLOOKUP(V$1,Bilanço!$1:$151,MATCH(Çeyreklik!$A11,Bilanço!$A:$A,0),0)),"") -> 0
A12: =Data!A83 -> BRÜT KAR (ZARAR) | B12: =IFERROR(IF($B$2="2022/3",IF(MID(B$2,6,7)="3",HLOOKUP(B$1,Bilanço!$1:$151,MATCH(Çeyreklik!$A12,Bilanço!$A:$A,0),0),HLOOKUP(B$1,Bilanço!$1:$151,MATCH(Çeyreklik!$A12,Bilanço!$A:$A,0),0)-HLOOKUP(A$1,Bilanço!$1:$151,MATCH(Çeyreklik!$A12,Bilanço!$A:$A,0),0)),IF(MID(B$2,6,7)="3",HLOOKUP(B$1,Bilanço!$1:$151,MATCH(Çeyreklik!$A12,Bilanço!$A:$A,0),0),HLOOKUP(B$1,Bilanço!$1:$151,MATCH(Çeyreklik!$A12,Bilanço!$A:$A,0),0)-HLOOKUP(Bilanço!$B$1,Bilanço!$1:$151,MATCH(Çeyreklik!$A12,Bilanço!$A:$A,0),0))),"") -> 587135000 | C12: =IFERROR(IF(MID(C$2,6,7)="3",HLOOKUP(C$1,Bilanço!$1:$151,MATCH(Çeyreklik!$A12,Bilanço!$A:$A,0),0),HLOOKUP(C$1,Bilanço!$1:$151,MATCH(Çeyreklik!$A12,Bilanço!$A:$A,0),0)-HLOOKUP(B$1,Bilanço!$1:$151,MATCH(Çeyreklik!$A12,Bilanço!$A:$A,0),0)),"") -> 808916000 | D12: =IFERROR(IF(MID(D$2,6,7)="3",HLOOKUP(D$1,Bilanço!$1:$151,MATCH(Çeyreklik!$A12,Bilanço!$A:$A,0),0),HLOOKUP(D$1,Bilanço!$1:$151,MATCH(Çeyreklik!$A12,Bilanço!$A:$A,0),0)-HLOOKUP(C$1,Bilanço!$1:$151,MATCH(Çeyreklik!$A12,Bilanço!$A:$A,0),0)),"") -> 824926000 | E12: =IFERROR(IF(MID(E$2,6,7)="3",HLOOKUP(E$1,Bilanço!$1:$151,MATCH(Çeyreklik!$A12,Bilanço!$A:$A,0),0),HLOOKUP(E$1,Bilanço!$1:$151,MATCH(Çeyreklik!$A12,Bilanço!$A:$A,0),0)-HLOOKUP(D$1,Bilanço!$1:$151,MATCH(Çeyreklik!$A12,Bilanço!$A:$A,0),0)),"") -> 862338000 | F12: =IFERROR(IF(MID(F$2,6,7)="3",HLOOKUP(F$1,Bilanço!$1:$151,MATCH(Çeyreklik!$A12,Bilanço!$A:$A,0),0),HLOOKUP(F$1,Bilanço!$1:$151,MATCH(Çeyreklik!$A12,Bilanço!$A:$A,0),0)-HLOOKUP(E$1,Bilanço!$1:$151,MATCH(Çeyreklik!$A12,Bilanço!$A:$A,0),0)),"") -> 711358000 | G12: =IFERROR(IF(MID(G$2,6,7)="3",HLOOKUP(G$1,Bilanço!$1:$151,MATCH(Çeyreklik!$A12,Bilanço!$A:$A,0),0),HLOOKUP(G$1,Bilanço!$1:$151,MATCH(Çeyreklik!$A12,Bilanço!$A:$A,0),0)-HLOOKUP(F$1,Bilanço!$1:$151,MATCH(Çeyreklik!$A12,Bilanço!$A:$A,0),0)),"") -> 804184000 | H12: =IFERROR(IF(MID(H$2,6,7)="3",HLOOKUP(H$1,Bilanço!$1:$151,MATCH(Çeyreklik!$A12,Bilanço!$A:$A,0),0),HLOOKUP(H$1,Bilanço!$1:$151,MATCH(Çeyreklik!$A12,Bilanço!$A:$A,0),0)-HLOOKUP(G$1,Bilanço!$1:$151,MATCH(Çeyreklik!$A12,Bilanço!$A:$A,0),0)),"") -> 1234535000 | I12: =IFERROR(IF(MID(I$2,6,7)="3",HLOOKUP(I$1,Bilanço!$1:$151,MATCH(Çeyreklik!$A12,Bilanço!$A:$A,0),0),HLOOKUP(I$1,Bilanço!$1:$151,MATCH(Çeyreklik!$A12,Bilanço!$A:$A,0),0)-HLOOKUP(H$1,Bilanço!$1:$151,MATCH(Çeyreklik!$A12,Bilanço!$A:$A,0),0)),"") -> 1849090000 | J12: =IFERROR(IF(MID(J$2,6,7)="3",HLOOKUP(J$1,Bilanço!$1:$151,MATCH(Çeyreklik!$A12,Bilanço!$A:$A,0),0),HLOOKUP(J$1,Bilanço!$1:$151,MATCH(Çeyreklik!$A12,Bilanço!$A:$A,0),0)-HLOOKUP(I$1,Bilanço!$1:$151,MATCH(Çeyreklik!$A12,Bilanço!$A:$A,0),0)),"") -> 1697710000 | ... W12: =IFERROR(IF(MID(W$2,6,7)="3",HLOOKUP(W$1,Bilanço!$1:$151,MATCH(Çeyreklik!$A12,Bilanço!$A:$A,0),0),HLOOKUP(W$1,Bilanço!$1:$151,MATCH(Çeyreklik!$A12,Bilanço!$A:$A,0),0)-HLOOKUP(V$1,Bilanço!$1:$151,MATCH(Çeyreklik!$A12,Bilanço!$A:$A,0),0)),"") -> 8618586000
